Workbook

Sheet 00_Settings
A1: ⚙ GLOBAL SETTINGS — Revenue & Margin Intelligence System
A2: Setting | B2: Selected Value | C2: Available Options / Notes
A3: Currency | B3: EUR | C3: EUR | USD | GBP | GEL
A4: Currency Symbol (auto) | B4: =CHOOSE(MATCH(B3,{"EUR","USD","GBP","GEL"},0),"€","$","£","₾") | C4: Auto-calculated
A6: SKU Category | B6: Beauty / Skincare | C6: Beauty / Skincare | Health & Supplements | Home & Kitchen | Apparel | Generic
A8: ━━ VAT POLICY
A9: VAT Treatment | B9: EXCLUDED from all margin & CM calculations throughout the model.
A10: Standard | B10: All prices, costs, and CM figures are EX-VAT.
A11: VAT Rate | B11: Stored in 07_Channel_Costs as reference only (supports future cash-flow extensions).
A12: Pricing note | B12: If list prices are VAT-inclusive, divide by (1 + VAT) before entering Base Price.
A14: 💡 Change yellow dropdowns → updates the workbook. All prices are EX-VAT. Data source: sales_orders.csv

Sheet 01_Summary
A1: 01 | EXECUTIVE SUMMARY — Revenue & Margin Intelligence (Dual-Lens)
A2: KEY METRICS (auto-calculated from sales_orders.csv)
A3: Total Gross Revenue | B3: =SUM('08_Sales_Orders'!I3:I62)
A4: Total Net Revenue | B4: =SUM('08_Sales_Orders'!M3:M62)
A5: Total Shipping Income | B5: =SUM('08_Sales_Orders'!L3:L62)
A6: Total CM — Amazon | B6: =SUMIF('02_SKU_Channel_PnL'!D5:D28,"Amazon",'02_SKU_Channel_PnL'!Z5:Z28)
A7: Total CM — DTC | B7: =SUMIF('02_SKU_Channel_PnL'!D5:D28,"DTC",'02_SKU_Channel_PnL'!Z5:Z28)
A8: Avg CM % — Amazon | B8: =AVERAGEIF('02_SKU_Channel_PnL'!D5:D28,"Amazon",'02_SKU_Channel_PnL'!Y5:Y28)
A9: Avg CM % — DTC | B9: =AVERAGEIF('02_SKU_Channel_PnL'!D5:D28,"DTC",'02_SKU_Channel_PnL'!Y5:Y28)
A11: SHEET DIRECTORY
A12: 00_Settings | B12: Currency & category selector. VAT policy (EX-VAT standard). Dual-lens policy.
A13: 01_Summary | B13: ← You are here. KPIs + sheet directory. Source: sales_orders.csv
A14: 02_SKU_Channel_PnL | B14: Full CM engine using Net Units (econ_units) from sales_orders.csv.
A15: 03_Kill_Optimize_Scale | B15: Decision matrix: SCALE / OPTIMIZE / KILL per SKU × channel.
A16: 04_Scenarios | B16: Planned extension: sensitivity and scenario matrix.
A17: 05_Working_Capital | B17: Planned extension: cash lock / working capital risk scoring.
A18: 06_Raw_SKU | B18: SKU master: base price and product variable costs. Blue = editable.
A19: 07_Channel_Costs | B19: Channel economics: fulfil vs shipping split, fees, returns, ads assumptions.
A20: 08_Sales_Orders | B20: Transactions from sales_orders.csv with Net Units (econ_units), Return Units, Shipping Income.
A21: 09_README | B21: Workbook documentation: policies, conventions, roadmap, dual-lens logic.
A23: DUAL-LENS v2.0: Net Units (econ_units) from CSV. Always ≥ 0. Single source of truth: data/raw/sales_orders.csv

Sheet 02_SKU_Channel_PnL
A1: 02 | SKU × CHANNEL P&L — Contribution Margin Engine (Ex-VAT, Dual-Lens)
A2: Currency: | B2: ='00_Settings'!B3 | C2: Symbol: | D2: ='00_Settings'!B4
A3: SKU INFO | E3: VOLUME | F3: REVENUE (EX-VAT) | N3: VARIABLE COST / UNIT | W3: MARGIN / UNIT | Z3: TOTAL CM | AA3: SIGNAL
A4: SKU ID | B4: SKU Name | C4: Subcat | D4: Channel | E4: Units Sold | F4: Base Price (ex-VAT) | G4: Discount % | H4: Net Price (ex-VAT) | I4: Gross Revenue | J4: Return Units | K4: Net Units | L4: Shipping Income | M4: Net Revenue | N4: COGS /unit | O4: Pkg + Freight | P4: Referral Fee | Q4: Fulfil Fee (3PL/FBA) | R4: Shipping Fee | S4: Ads /unit | T4: Returns Rev Loss | U4: Returns COGS Loss | V4: Return Proc Fee | W4: Total VC / econ unit | X4: CM / unit (ex-VAT) | Y4: CM % (ex-VAT) | Z4: Total CM (€) | AA4: Signal
A5: SKU-001 | B5: Vitamin C Brightening Serum 30ml | C5: Serum | D5: Amazon | E5: =SUMIFS('08_Sales_Orders'!$E$3:$E$62,'08_Sales_Orders'!$B$3:$B$62,A5,'08_Sales_Orders'!$D$3:$D$62,D5) | F5: 34.99 | G5: =IF(F5=0, 0, 1-(H5/F5)) | H5: =IF(E5=0, 0, I5/E5) | I5: =SUMIFS('08_Sales_Orders'!$I$3:$I$62,'08_Sales_Orders'!$B$3:$B$62,A5,'08_Sales_Orders'!$D$3:$D$62,D5) | J5: =SUMIFS('08_Sales_Orders'!$J$3:$J$62,'08_Sales_Orders'!$B$3:$B$62,A5,'08_Sales_Orders'!$D$3:$D$62,D5) | K5: =SUMIFS('08_Sales_Orders'!$K$3:$K$62,'08_Sales_Orders'!$B$3:$B$62,A5,'08_Sales_Orders'!$D$3:$D$62,D5) | L5: =SUMIFS('08_Sales_Orders'!$L$3:$L$62,'08_Sales_Orders'!$B$3:$B$62,A5,'08_Sales_Orders'!$D$3:$D$62,D5) | M5: =SUMIFS('08_Sales_Orders'!$M$3:$M$62,'08_Sales_Orders'!$B$3:$B$62,A5,'08_Sales_Orders'!$D$3:$D$62,D5) | N5: 6.2 | O5: 2.9 | P5: ='07_Channel_Costs'!B3*H5 | Q5: ='07_Channel_Costs'!C3 | R5: ='07_Channel_Costs'!D3 | S5: ='07_Channel_Costs'!E3*H5 | T5: =J5*H5 | U5: =J5*'07_Channel_Costs'!F3*N5 | V5: =J5*'07_Channel_Costs'!G3 | W5: =IF(K5=0,0,(E5*(N5+O5) + K5*(P5+Q5+R5+S5) + U5 + V5)/K5) | X5: =IF(K5=0,0,(M5-(E5*(N5+O5) + K5*(P5+Q5+R5+S5) + U5 + V5))/K5) | Y5: =IF(M5=0,"",(M5-(E5*(N5+O5) + K5*(P5+Q5+R5+S5) + U5 + V5))/M5) | Z5: =M5-(E5*(N5+O5) + K5*(P5+Q5+R5+S5) + U5 + V5) | AA5: =IF(Y5>=0.4,"🚀 SCALE",IF(Y5>=0.25,"⚙ OPTIMIZE",IF(Y5>=0,"⚠ REVIEW","🔴 KILL")))
A6: SKU-001 | B6: Vitamin C Brightening Serum 30ml | C6: Serum | D6: DTC | E6: =SUMIFS('08_Sales_Orders'!$E$3:$E$62,'08_Sales_Orders'!$B$3:$B$62,A6,'08_Sales_Orders'!$D$3:$D$62,D6) | F6: 34.99 | G6: =IF(F6=0, 0, 1-(H6/F6)) | H6: =IF(E6=0, 0, I6/E6) | I6: =SUMIFS('08_Sales_Orders'!$I$3:$I$62,'08_Sales_Orders'!$B$3:$B$62,A6,'08_Sales_Orders'!$D$3:$D$62,D6) | J6: =SUMIFS('08_Sales_Orders'!$J$3:$J$62,'08_Sales_Orders'!$B$3:$B$62,A6,'08_Sales_Orders'!$D$3:$D$62,D6) | K6: =SUMIFS('08_Sales_Orders'!$K$3:$K$62,'08_Sales_Orders'!$B$3:$B$62,A6,'08_Sales_Orders'!$D$3:$D$62,D6) | L6: =SUMIFS('08_Sales_Orders'!$L$3:$L$62,'08_Sales_Orders'!$B$3:$B$62,A6,'08_Sales_Orders'!$D$3:$D$62,D6) | M6: =SUMIFS('08_Sales_Orders'!$M$3:$M$62,'08_Sales_Orders'!$B$3:$B$62,A6,'08_Sales_Orders'!$D$3:$D$62,D6) | N6: 6.2 | O6: 2.9 | P6: ='07_Channel_Costs'!B4*H6 | Q6: ='07_Channel_Costs'!C4 | R6: ='07_Channel_Costs'!D4 | S6: ='07_Channel_Costs'!E4*H6 | T6: =J6*H6 | U6: =J6*'07_Channel_Costs'!F4*N6 | V6: =J6*'07_Channel_Costs'!G4 | W6: =IF(K6=0,0,(E6*(N6+O6) + K6*(P6+Q6+R6+S6) + U6 + V6)/K6) | X6: =IF(K6=0,0,(M6-(E6*(N6+O6) + K6*(P6+Q6+R6+S6) + U6 + V6))/K6) | Y6: =IF(M6=0,"",(M6-(E6*(N6+O6) + K6*(P6+Q6+R6+S6) + U6 + V6))/M6) | Z6: =M6-(E6*(N6+O6) + K6*(P6+Q6+R6+S6) + U6 + V6) | AA6: =IF(Y6>=0.4,"🚀 SCALE",IF(Y6>=0.25,"⚙ OPTIMIZE",IF(Y6>=0,"⚠ REVIEW","🔴 KILL")))
A7: SKU-002 | B7: Hyaluronic Acid Moisturiser 50ml | C7: Moisturiser | D7: Amazon | E7: =SUMIFS('08_Sales_Orders'!$E$3:$E$62,'08_Sales_Orders'!$B$3:$B$62,A7,'08_Sales_Orders'!$D$3:$D$62,D7) | F7: 28.99 | G7: =IF(F7=0, 0, 1-(H7/F7)) | H7: =IF(E7=0, 0, I7/E7) | I7: =SUMIFS('08_Sales_Orders'!$I$3:$I$62,'08_Sales_Orders'!$B$3:$B$62,A7,'08_Sales_Orders'!$D$3:$D$62,D7) | J7: =SUMIFS('08_Sales_Orders'!$J$3:$J$62,'08_Sales_Orders'!$B$3:$B$62,A7,'08_Sales_Orders'!$D$3:$D$62,D7) | K7: =SUMIFS('08_Sales_Orders'!$K$3:$K$62,'08_Sales_Orders'!$B$3:$B$62,A7,'08_Sales_Orders'!$D$3:$D$62,D7) | L7: =SUMIFS('08_Sales_Orders'!$L$3:$L$62,'08_Sales_Orders'!$B$3:$B$62,A7,'08_Sales_Orders'!$D$3:$D$62,D7) | M7: =SUMIFS('08_Sales_Orders'!$M$3:$M$62,'08_Sales_Orders'!$B$3:$B$62,A7,'08_Sales_Orders'!$D$3:$D$62,D7) | N7: 5.4 | O7: 2.55 | P7: ='07_Channel_Costs'!B3*H7 | Q7: ='07_Channel_Costs'!C3 | R7: ='07_Channel_Costs'!D3 | S7: ='07_Channel_Costs'!E3*H7 | T7: =J7*H7 | U7: =J7*'07_Channel_Costs'!F3*N7 | V7: =J7*'07_Channel_Costs'!G3 | W7: =IF(K7=0,0,(E7*(N7+O7) + K7*(P7+Q7+R7+S7) + U7 + V7)/K7) | X7: =IF(K7=0,0,(M7-(E7*(N7+O7) + K7*(P7+Q7+R7+S7) + U7 + V7))/K7) | Y7: =IF(M7=0,"",(M7-(E7*(N7+O7) + K7*(P7+Q7+R7+S7) + U7 + V7))/M7) | Z7: =M7-(E7*(N7+O7) + K7*(P7+Q7+R7+S7) + U7 + V7) | AA7: =IF(Y7>=0.4,"🚀 SCALE",IF(Y7>=0.25,"⚙ OPTIMIZE",IF(Y7>=0,"⚠ REVIEW","🔴 KILL")))
A8: SKU-002 | B8: Hyaluronic Acid Moisturiser 50ml | C8: Moisturiser | D8: DTC | E8: =SUMIFS('08_Sales_Orders'!$E$3:$E$62,'08_Sales_Orders'!$B$3:$B$62,A8,'08_Sales_Orders'!$D$3:$D$62,D8) | F8: 28.99 | G8: =IF(F8=0, 0, 1-(H8/F8)) | H8: =IF(E8=0, 0, I8/E8) | I8: =SUMIFS('08_Sales_Orders'!$I$3:$I$62,'08_Sales_Orders'!$B$3:$B$62,A8,'08_Sales_Orders'!$D$3:$D$62,D8) | J8: =SUMIFS('08_Sales_Orders'!$J$3:$J$62,'08_Sales_Orders'!$B$3:$B$62,A8,'08_Sales_Orders'!$D$3:$D$62,D8) | K8: =SUMIFS('08_Sales_Orders'!$K$3:$K$62,'08_Sales_Orders'!$B$3:$B$62,A8,'08_Sales_Orders'!$D$3:$D$62,D8) | L8: =SUMIFS('08_Sales_Orders'!$L$3:$L$62,'08_Sales_Orders'!$B$3:$B$62,A8,'08_Sales_Orders'!$D$3:$D$62,D8) | M8: =SUMIFS('08_Sales_Orders'!$M$3:$M$62,'08_Sales_Orders'!$B$3:$B$62,A8,'08_Sales_Orders'!$D$3:$D$62,D8) | N8: 5.4 | O8: 2.55 | P8: ='07_Channel_Costs'!B4*H8 | Q8: ='07_Channel_Costs'!C4 | R8: ='07_Channel_Costs'!D4 | S8: ='07_Channel_Costs'!E4*H8 | T8: =J8*H8 | U8: =J8*'07_Channel_Costs'!F4*N8 | V8: =J8*'07_Channel_Costs'!G4 | W8: =IF(K8=0,0,(E8*(N8+O8) + K8*(P8+Q8+R8+S8) + U8 + V8)/K8) | X8: =IF(K8=0,0,(M8-(E8*(N8+O8) + K8*(P8+Q8+R8+S8) + U8 + V8))/K8) | Y8: =IF(M8=0,"",(M8-(E8*(N8+O8) + K8*(P8+Q8+R8+S8) + U8 + V8))/M8) | Z8: =M8-(E8*(N8+O8) + K8*(P8+Q8+R8+S8) + U8 + V8) | AA8: =IF(Y8>=0.4,"🚀 SCALE",IF(Y8>=0.25,"⚙ OPTIMIZE",IF(Y8>=0,"⚠ REVIEW","🔴 KILL")))
A9: SKU-003 | B9: Retinol Night Cream 30ml | C9: Cream | D9: Amazon | E9: =SUMIFS('08_Sales_Orders'!$E$3:$E$62,'08_Sales_Orders'!$B$3:$B$62,A9,'08_Sales_Orders'!$D$3:$D$62,D9) | F9: 42.99 | G9: =IF(F9=0, 0, 1-(H9/F9)) | H9: =IF(E9=0, 0, I9/E9) | I9: =SUMIFS('08_Sales_Orders'!$I$3:$I$62,'08_Sales_Orders'!$B$3:$B$62,A9,'08_Sales_Orders'!$D$3:$D$62,D9) | J9: =SUMIFS('08_Sales_Orders'!$J$3:$J$62,'08_Sales_Orders'!$B$3:$B$62,A9,'08_Sales_Orders'!$D$3:$D$62,D9) | K9: =SUMIFS('08_Sales_Orders'!$K$3:$K$62,'08_Sales_Orders'!$B$3:$B$62,A9,'08_Sales_Orders'!$D$3:$D$62,D9) | L9: =SUMIFS('08_Sales_Orders'!$L$3:$L$62,'08_Sales_Orders'!$B$3:$B$62,A9,'08_Sales_Orders'!$D$3:$D$62,D9) | M9: =SUMIFS('08_Sales_Orders'!$M$3:$M$62,'08_Sales_Orders'!$B$3:$B$62,A9,'08_Sales_Orders'!$D$3:$D$62,D9) | N9: 8.5 | O9: 3.1 | P9: ='07_Channel_Costs'!B3*H9 | Q9: ='07_Channel_Costs'!C3 | R9: ='07_Channel_Costs'!D3 | S9: ='07_Channel_Costs'!E3*H9 | T9: =J9*H9 | U9: =J9*'07_Channel_Costs'!F3*N9 | V9: =J9*'07_Channel_Costs'!G3 | W9: =IF(K9=0,0,(E9*(N9+O9) + K9*(P9+Q9+R9+S9) + U9 + V9)/K9) | X9: =IF(K9=0,0,(M9-(E9*(N9+O9) + K9*(P9+Q9+R9+S9) + U9 + V9))/K9) | Y9: =IF(M9=0,"",(M9-(E9*(N9+O9) + K9*(P9+Q9+R9+S9) + U9 + V9))/M9) | Z9: =M9-(E9*(N9+O9) + K9*(P9+Q9+R9+S9) + U9 + V9) | AA9: =IF(Y9>=0.4,"🚀 SCALE",IF(Y9>=0.25,"⚙ OPTIMIZE",IF(Y9>=0,"⚠ REVIEW","🔴 KILL")))
A10: SKU-003 | B10: Retinol Night Cream 30ml | C10: Cream | D10: DTC | E10: =SUMIFS('08_Sales_Orders'!$E$3:$E$62,'08_Sales_Orders'!$B$3:$B$62,A10,'08_Sales_Orders'!$D$3:$D$62,D10) | F10: 42.99 | G10: =IF(F10=0, 0, 1-(H10/F10)) | H10: =IF(E10=0, 0, I10/E10) | I10: =SUMIFS('08_Sales_Orders'!$I$3:$I$62,'08_Sales_Orders'!$B$3:$B$62,A10,'08_Sales_Orders'!$D$3:$D$62,D10) | J10: =SUMIFS('08_Sales_Orders'!$J$3:$J$62,'08_Sales_Orders'!$B$3:$B$62,A10,'08_Sales_Orders'!$D$3:$D$62,D10) | K10: =SUMIFS('08_Sales_Orders'!$K$3:$K$62,'08_Sales_Orders'!$B$3:$B$62,A10,'08_Sales_Orders'!$D$3:$D$62,D10) | L10: =SUMIFS('08_Sales_Orders'!$L$3:$L$62,'08_Sales_Orders'!$B$3:$B$62,A10,'08_Sales_Orders'!$D$3:$D$62,D10) | M10: =SUMIFS('08_Sales_Orders'!$M$3:$M$62,'08_Sales_Orders'!$B$3:$B$62,A10,'08_Sales_Orders'!$D$3:$D$62,D10) | N10: 8.5 | O10: 3.1 | P10: ='07_Channel_Costs'!B4*H10 | Q10: ='07_Channel_Costs'!C4 | R10: ='07_Channel_Costs'!D4 | S10: ='07_Channel_Costs'!E4*H10 | T10: =J10*H10 | U10: =J10*'07_Channel_Costs'!F4*N10 | V10: =J10*'07_Channel_Costs'!G4 | W10: =IF(K10=0,0,(E10*(N10+O10) + K10*(P10+Q10+R10+S10) + U10 + V10)/K10) | X10: =IF(K10=0,0,(M10-(E10*(N10+O10) + K10*(P10+Q10+R10+S10) + U10 + V10))/K10) | Y10: =IF(M10=0,"",(M10-(E10*(N10+O10) + K10*(P10+Q10+R10+S10) + U10 + V10))/M10) | Z10: =M10-(E10*(N10+O10) + K10*(P10+Q10+R10+S10) + U10 + V10) | AA10: =IF(Y10>=0.4,"🚀 SCALE",IF(Y10>=0.25,"⚙ OPTIMIZE",IF(Y10>=0,"⚠ REVIEW","🔴 KILL")))
A11: SKU-004 | B11: SPF 50+ Daily Sunscreen 75ml | C11: Sunscreen | D11: Amazon | E11: =SUMIFS('08_Sales_Orders'!$E$3:$E$62,'08_Sales_Orders'!$B$3:$B$62,A11,'08_Sales_Orders'!$D$3:$D$62,D11) | F11: 22.99 | G11: =IF(F11=0, 0, 1-(H11/F11)) | H11: =IF(E11=0, 0, I11/E11) | I11: =SUMIFS('08_Sales_Orders'!$I$3:$I$62,'08_Sales_Orders'!$B$3:$B$62,A11,'08_Sales_Orders'!$D$3:$D$62,D11) | J11: =SUMIFS('08_Sales_Orders'!$J$3:$J$62,'08_Sales_Orders'!$B$3:$B$62,A11,'08_Sales_Orders'!$D$3:$D$62,D11) | K11: =SUMIFS('08_Sales_Orders'!$K$3:$K$62,'08_Sales_Orders'!$B$3:$B$62,A11,'08_Sales_Orders'!$D$3:$D$62,D11) | L11: =SUMIFS('08_Sales_Orders'!$L$3:$L$62,'08_Sales_Orders'!$B$3:$B$62,A11,'08_Sales_Orders'!$D$3:$D$62,D11) | M11: =SUMIFS('08_Sales_Orders'!$M$3:$M$62,'08_Sales_Orders'!$B$3:$B$62,A11,'08_Sales_Orders'!$D$3:$D$62,D11) | N11: 4.1 | O11: 2.25 | P11: ='07_Channel_Costs'!B3*H11 | Q11: ='07_Channel_Costs'!C3 | R11: ='07_Channel_Costs'!D3 | S11: ='07_Channel_Costs'!E3*H11 | T11: =J11*H11 | U11: =J11*'07_Channel_Costs'!F3*N11 | V11: =J11*'07_Channel_Costs'!G3 | W11: =IF(K11=0,0,(E11*(N11+O11) + K11*(P11+Q11+R11+S11) + U11 + V11)/K11) | X11: =IF(K11=0,0,(M11-(E11*(N11+O11) + K11*(P11+Q11+R11+S11) + U11 + V11))/K11) | Y11: =IF(M11=0,"",(M11-(E11*(N11+O11) + K11*(P11+Q11+R11+S11) + U11 + V11))/M11) | Z11: =M11-(E11*(N11+O11) + K11*(P11+Q11+R11+S11) + U11 + V11) | AA11: =IF(Y11>=0.4,"🚀 SCALE",IF(Y11>=0.25,"⚙ OPTIMIZE",IF(Y11>=0,"⚠ REVIEW","🔴 KILL")))
A12: SKU-004 | B12: SPF 50+ Daily Sunscreen 75ml | C12: Sunscreen | D12: DTC | E12: =SUMIFS('08_Sales_Orders'!$E$3:$E$62,'08_Sales_Orders'!$B$3:$B$62,A12,'08_Sales_Orders'!$D$3:$D$62,D12) | F12: 22.99 | G12: =IF(F12=0, 0, 1-(H12/F12)) | H12: =IF(E12=0, 0, I12/E12) | I12: =SUMIFS('08_Sales_Orders'!$I$3:$I$62,'08_Sales_Orders'!$B$3:$B$62,A12,'08_Sales_Orders'!$D$3:$D$62,D12) | J12: =SUMIFS('08_Sales_Orders'!$J$3:$J$62,'08_Sales_Orders'!$B$3:$B$62,A12,'08_Sales_Orders'!$D$3:$D$62,D12) | K12: =SUMIFS('08_Sales_Orders'!$K$3:$K$62,'08_Sales_Orders'!$B$3:$B$62,A12,'08_Sales_Orders'!$D$3:$D$62,D12) | L12: =SUMIFS('08_Sales_Orders'!$L$3:$L$62,'08_Sales_Orders'!$B$3:$B$62,A12,'08_Sales_Orders'!$D$3:$D$62,D12) | M12: =SUMIFS('08_Sales_Orders'!$M$3:$M$62,'08_Sales_Orders'!$B$3:$B$62,A12,'08_Sales_Orders'!$D$3:$D$62,D12) | N12: 4.1 | O12: 2.25 | P12: ='07_Channel_Costs'!B4*H12 | Q12: ='07_Channel_Costs'!C4 | R12: ='07_Channel_Costs'!D4 | S12: ='07_Channel_Costs'!E4*H12 | T12: =J12*H12 | U12: =J12*'07_Channel_Costs'!F4*N12 | V12: =J12*'07_Channel_Costs'!G4 | W12: =IF(K12=0,0,(E12*(N12+O12) + K12*(P12+Q12+R12+S12) + U12 + V12)/K12) | X12: =IF(K12=0,0,(M12-(E12*(N12+O12) + K12*(P12+Q12+R12+S12) + U12 + V12))/K12) | Y12: =IF(M12=0,"",(M12-(E12*(N12+O12) + K12*(P12+Q12+R12+S12) + U12 + V12))/M12) | Z12: =M12-(E12*(N12+O12) + K12*(P12+Q12+R12+S12) + U12 + V12) | AA12: =IF(Y12>=0.4,"🚀 SCALE",IF(Y12>=0.25,"⚙ OPTIMIZE",IF(Y12>=0,"⚠ REVIEW","🔴 KILL")))
A13: SKU-005 | B13: AHA/BHA Exfoliating Toner 200ml | C13: Toner | D13: Amazon | E13: =SUMIFS('08_Sales_Orders'!$E$3:$E$62,'08_Sales_Orders'!$B$3:$B$62,A13,'08_Sales_Orders'!$D$3:$D$62,D13) | F13: 26.99 | G13: =IF(F13=0, 0, 1-(H13/F13)) | H13: =IF(E13=0, 0, I13/E13) | I13: =SUMIFS('08_Sales_Orders'!$I$3:$I$62,'08_Sales_Orders'!$B$3:$B$62,A13,'08_Sales_Orders'!$D$3:$D$62,D13) | J13: =SUMIFS('08_Sales_Orders'!$J$3:$J$62,'08_Sales_Orders'!$B$3:$B$62,A13,'08_Sales_Orders'!$D$3:$D$62,D13) | K13: =SUMIFS('08_Sales_Orders'!$K$3:$K$62,'08_Sales_Orders'!$B$3:$B$62,A13,'08_Sales_Orders'!$D$3:$D$62,D13) | L13: =SUMIFS('08_Sales_Orders'!$L$3:$L$62,'08_Sales_Orders'!$B$3:$B$62,A13,'08_Sales_Orders'!$D$3:$D$62,D13) | M13: =SUMIFS('08_Sales_Orders'!$M$3:$M$62,'08_Sales_Orders'!$B$3:$B$62,A13,'08_Sales_Orders'!$D$3:$D$62,D13) | N13: 4.8 | O13: 2.45 | P13: ='07_Channel_Costs'!B3*H13 | Q13: ='07_Channel_Costs'!C3 | R13: ='07_Channel_Costs'!D3 | S13: ='07_Channel_Costs'!E3*H13 | T13: =J13*H13 | U13: =J13*'07_Channel_Costs'!F3*N13 | V13: =J13*'07_Channel_Costs'!G3 | W13: =IF(K13=0,0,(E13*(N13+O13) + K13*(P13+Q13+R13+S13) + U13 + V13)/K13) | X13: =IF(K13=0,0,(M13-(E13*(N13+O13) + K13*(P13+Q13+R13+S13) + U13 + V13))/K13) | Y13: =IF(M13=0,"",(M13-(E13*(N13+O13) + K13*(P13+Q13+R13+S13) + U13 + V13))/M13) | Z13: =M13-(E13*(N13+O13) + K13*(P13+Q13+R13+S13) + U13 + V13) | AA13: =IF(Y13>=0.4,"🚀 SCALE",IF(Y13>=0.25,"⚙ OPTIMIZE",IF(Y13>=0,"⚠ REVIEW","🔴 KILL")))
A14: SKU-005 | B14: AHA/BHA Exfoliating Toner 200ml | C14: Toner | D14: DTC | E14: =SUMIFS('08_Sales_Orders'!$E$3:$E$62,'08_Sales_Orders'!$B$3:$B$62,A14,'08_Sales_Orders'!$D$3:$D$62,D14) | F14: 26.99 | G14: =IF(F14=0, 0, 1-(H14/F14)) | H14: =IF(E14=0, 0, I14/E14) | I14: =SUMIFS('08_Sales_Orders'!$I$3:$I$62,'08_Sales_Orders'!$B$3:$B$62,A14,'08_Sales_Orders'!$D$3:$D$62,D14) | J14: =SUMIFS('08_Sales_Orders'!$J$3:$J$62,'08_Sales_Orders'!$B$3:$B$62,A14,'08_Sales_Orders'!$D$3:$D$62,D14) | K14: =SUMIFS('08_Sales_Orders'!$K$3:$K$62,'08_Sales_Orders'!$B$3:$B$62,A14,'08_Sales_Orders'!$D$3:$D$62,D14) | L14: =SUMIFS('08_Sales_Orders'!$L$3:$L$62,'08_Sales_Orders'!$B$3:$B$62,A14,'08_Sales_Orders'!$D$3:$D$62,D14) | M14: =SUMIFS('08_Sales_Orders'!$M$3:$M$62,'08_Sales_Orders'!$B$3:$B$62,A14,'08_Sales_Orders'!$D$3:$D$62,D14) | N14: 4.8 | O14: 2.45 | P14: ='07_Channel_Costs'!B4*H14 | Q14: ='07_Channel_Costs'!C4 | R14: ='07_Channel_Costs'!D4 | S14: ='07_Channel_Costs'!E4*H14 | T14: =J14*H14 | U14: =J14*'07_Channel_Costs'!F4*N14 | V14: =J14*'07_Channel_Costs'!G4 | W14: =IF(K14=0,0,(E14*(N14+O14) + K14*(P14+Q14+R14+S14) + U14 + V14)/K14) | X14: =IF(K14=0,0,(M14-(E14*(N14+O14) + K14*(P14+Q14+R14+S14) + U14 + V14))/K14) | Y14: =IF(M14=0,"",(M14-(E14*(N14+O14) + K14*(P14+Q14+R14+S14) + U14 + V14))/M14) | Z14: =M14-(E14*(N14+O14) + K14*(P14+Q14+R14+S14) + U14 + V14) | AA14: =IF(Y14>=0.4,"🚀 SCALE",IF(Y14>=0.25,"⚙ OPTIMIZE",IF(Y14>=0,"⚠ REVIEW","🔴 KILL")))
A15: SKU-006 | B15: Niacinamide Pore Minimiser Serum | C15: Serum | D15: Amazon | E15: =SUMIFS('08_Sales_Orders'!$E$3:$E$62,'08_Sales_Orders'!$B$3:$B$62,A15,'08_Sales_Orders'!$D$3:$D$62,D15) | F15: 31.99 | G15: =IF(F15=0, 0, 1-(H15/F15)) | H15: =IF(E15=0, 0, I15/E15) | I15: =SUMIFS('08_Sales_Orders'!$I$3:$I$62,'08_Sales_Orders'!$B$3:$B$62,A15,'08_Sales_Orders'!$D$3:$D$62,D15) | J15: =SUMIFS('08_Sales_Orders'!$J$3:$J$62,'08_Sales_Orders'!$B$3:$B$62,A15,'08_Sales_Orders'!$D$3:$D$62,D15) | K15: =SUMIFS('08_Sales_Orders'!$K$3:$K$62,'08_Sales_Orders'!$B$3:$B$62,A15,'08_Sales_Orders'!$D$3:$D$62,D15) | L15: =SUMIFS('08_Sales_Orders'!$L$3:$L$62,'08_Sales_Orders'!$B$3:$B$62,A15,'08_Sales_Orders'!$D$3:$D$62,D15) | M15: =SUMIFS('08_Sales_Orders'!$M$3:$M$62,'08_Sales_Orders'!$B$3:$B$62,A15,'08_Sales_Orders'!$D$3:$D$62,D15) | N15: 5.9 | O15: 2.8 | P15: ='07_Channel_Costs'!B3*H15 | Q15: ='07_Channel_Costs'!C3 | R15: ='07_Channel_Costs'!D3 | S15: ='07_Channel_Costs'!E3*H15 | T15: =J15*H15 | U15: =J15*'07_Channel_Costs'!F3*N15 | V15: =J15*'07_Channel_Costs'!G3 | W15: =IF(K15=0,0,(E15*(N15+O15) + K15*(P15+Q15+R15+S15) + U15 + V15)/K15) | X15: =IF(K15=0,0,(M15-(E15*(N15+O15) + K15*(P15+Q15+R15+S15) + U15 + V15))/K15) | Y15: =IF(M15=0,"",(M15-(E15*(N15+O15) + K15*(P15+Q15+R15+S15) + U15 + V15))/M15) | Z15: =M15-(E15*(N15+O15) + K15*(P15+Q15+R15+S15) + U15 + V15) | AA15: =IF(Y15>=0.4,"🚀 SCALE",IF(Y15>=0.25,"⚙ OPTIMIZE",IF(Y15>=0,"⚠ REVIEW","🔴 KILL")))
A16: SKU-006 | B16: Niacinamide Pore Minimiser Serum | C16: Serum | D16: DTC | E16: =SUMIFS('08_Sales_Orders'!$E$3:$E$62,'08_Sales_Orders'!$B$3:$B$62,A16,'08_Sales_Orders'!$D$3:$D$62,D16) | F16: 31.99 | G16: =IF(F16=0, 0, 1-(H16/F16)) | H16: =IF(E16=0, 0, I16/E16) | I16: =SUMIFS('08_Sales_Orders'!$I$3:$I$62,'08_Sales_Orders'!$B$3:$B$62,A16,'08_Sales_Orders'!$D$3:$D$62,D16) | J16: =SUMIFS('08_Sales_Orders'!$J$3:$J$62,'08_Sales_Orders'!$B$3:$B$62,A16,'08_Sales_Orders'!$D$3:$D$62,D16) | K16: =SUMIFS('08_Sales_Orders'!$K$3:$K$62,'08_Sales_Orders'!$B$3:$B$62,A16,'08_Sales_Orders'!$D$3:$D$62,D16) | L16: =SUMIFS('08_Sales_Orders'!$L$3:$L$62,'08_Sales_Orders'!$B$3:$B$62,A16,'08_Sales_Orders'!$D$3:$D$62,D16) | M16: =SUMIFS('08_Sales_Orders'!$M$3:$M$62,'08_Sales_Orders'!$B$3:$B$62,A16,'08_Sales_Orders'!$D$3:$D$62,D16) | N16: 5.9 | O16: 2.8 | P16: ='07_Channel_Costs'!B4*H16 | Q16: ='07_Channel_Costs'!C4 | R16: ='07_Channel_Costs'!D4 | S16: ='07_Channel_Costs'!E4*H16 | T16: =J16*H16 | U16: =J16*'07_Channel_Costs'!F4*N16 | V16: =J16*'07_Channel_Costs'!G4 | W16: =IF(K16=0,0,(E16*(N16+O16) + K16*(P16+Q16+R16+S16) + U16 + V16)/K16) | X16: =IF(K16=0,0,(M16-(E16*(N16+O16) + K16*(P16+Q16+R16+S16) + U16 + V16))/K16) | Y16: =IF(M16=0,"",(M16-(E16*(N16+O16) + K16*(P16+Q16+R16+S16) + U16 + V16))/M16) | Z16: =M16-(E16*(N16+O16) + K16*(P16+Q16+R16+S16) + U16 + V16) | AA16: =IF(Y16>=0.4,"🚀 SCALE",IF(Y16>=0.25,"⚙ OPTIMIZE",IF(Y16>=0,"⚠ REVIEW","🔴 KILL")))
A17: SKU-007 | B17: Collagen Boosting Eye Cream 15ml | C17: Eye Care | D17: Amazon | E17: =SUMIFS('08_Sales_Orders'!$E$3:$E$62,'08_Sales_Orders'!$B$3:$B$62,A17,'08_Sales_Orders'!$D$3:$D$62,D17) | F17: 38.99 | G17: =IF(F17=0, 0, 1-(H17/F17)) | H17: =IF(E17=0, 0, I17/E17) | I17: =SUMIFS('08_Sales_Orders'!$I$3:$I$62,'08_Sales_Orders'!$B$3:$B$62,A17,'08_Sales_Orders'!$D$3:$D$62,D17) | J17: =SUMIFS('08_Sales_Orders'!$J$3:$J$62,'08_Sales_Orders'!$B$3:$B$62,A17,'08_Sales_Orders'!$D$3:$D$62,D17) | K17: =SUMIFS('08_Sales_Orders'!$K$3:$K$62,'08_Sales_Orders'!$B$3:$B$62,A17,'08_Sales_Orders'!$D$3:$D$62,D17) | L17: =SUMIFS('08_Sales_Orders'!$L$3:$L$62,'08_Sales_Orders'!$B$3:$B$62,A17,'08_Sales_Orders'!$D$3:$D$62,D17) | M17: =SUMIFS('08_Sales_Orders'!$M$3:$M$62,'08_Sales_Orders'!$B$3:$B$62,A17,'08_Sales_Orders'!$D$3:$D$62,D17) | N17: 7.2 | O17: 3 | P17: ='07_Channel_Costs'!B3*H17 | Q17: ='07_Channel_Costs'!C3 | R17: ='07_Channel_Costs'!D3 | S17: ='07_Channel_Costs'!E3*H17 | T17: =J17*H17 | U17: =J17*'07_Channel_Costs'!F3*N17 | V17: =J17*'07_Channel_Costs'!G3 | W17: =IF(K17=0,0,(E17*(N17+O17) + K17*(P17+Q17+R17+S17) + U17 + V17)/K17) | X17: =IF(K17=0,0,(M17-(E17*(N17+O17) + K17*(P17+Q17+R17+S17) + U17 + V17))/K17) | Y17: =IF(M17=0,"",(M17-(E17*(N17+O17) + K17*(P17+Q17+R17+S17) + U17 + V17))/M17) | Z17: =M17-(E17*(N17+O17) + K17*(P17+Q17+R17+S17) + U17 + V17) | AA17: =IF(Y17>=0.4,"🚀 SCALE",IF(Y17>=0.25,"⚙ OPTIMIZE",IF(Y17>=0,"⚠ REVIEW","🔴 KILL")))
A18: SKU-007 | B18: Collagen Boosting Eye Cream 15ml | C18: Eye Care | D18: DTC | E18: =SUMIFS('08_Sales_Orders'!$E$3:$E$62,'08_Sales_Orders'!$B$3:$B$62,A18,'08_Sales_Orders'!$D$3:$D$62,D18) | F18: 38.99 | G18: =IF(F18=0, 0, 1-(H18/F18)) | H18: =IF(E18=0, 0, I18/E18) | I18: =SUMIFS('08_Sales_Orders'!$I$3:$I$62,'08_Sales_Orders'!$B$3:$B$62,A18,'08_Sales_Orders'!$D$3:$D$62,D18) | J18: =SUMIFS('08_Sales_Orders'!$J$3:$J$62,'08_Sales_Orders'!$B$3:$B$62,A18,'08_Sales_Orders'!$D$3:$D$62,D18) | K18: =SUMIFS('08_Sales_Orders'!$K$3:$K$62,'08_Sales_Orders'!$B$3:$B$62,A18,'08_Sales_Orders'!$D$3:$D$62,D18) | L18: =SUMIFS('08_Sales_Orders'!$L$3:$L$62,'08_Sales_Orders'!$B$3:$B$62,A18,'08_Sales_Orders'!$D$3:$D$62,D18) | M18: =SUMIFS('08_Sales_Orders'!$M$3:$M$62,'08_Sales_Orders'!$B$3:$B$62,A18,'08_Sales_Orders'!$D$3:$D$62,D18) | N18: 7.2 | O18: 3 | P18: ='07_Channel_Costs'!B4*H18 | Q18: ='07_Channel_Costs'!C4 | R18: ='07_Channel_Costs'!D4 | S18: ='07_Channel_Costs'!E4*H18 | T18: =J18*H18 | U18: =J18*'07_Channel_Costs'!F4*N18 | V18: =J18*'07_Channel_Costs'!G4 | W18: =IF(K18=0,0,(E18*(N18+O18) + K18*(P18+Q18+R18+S18) + U18 + V18)/K18) | X18: =IF(K18=0,0,(M18-(E18*(N18+O18) + K18*(P18+Q18+R18+S18) + U18 + V18))/K18) | Y18: =IF(M18=0,"",(M18-(E18*(N18+O18) + K18*(P18+Q18+R18+S18) + U18 + V18))/M18) | Z18: =M18-(E18*(N18+O18) + K18*(P18+Q18+R18+S18) + U18 + V18) | AA18: =IF(Y18>=0.4,"🚀 SCALE",IF(Y18>=0.25,"⚙ OPTIMIZE",IF(Y18>=0,"⚠ REVIEW","🔴 KILL")))
A19: SKU-008 | B19: Rose Hip Facial Oil 30ml | C19: Facial Oil | D19: Amazon | E19: =SUMIFS('08_Sales_Orders'!$E$3:$E$62,'08_Sales_Orders'!$B$3:$B$62,A19,'08_Sales_Orders'!$D$3:$D$62,D19) | F19: 35.99 | G19: =IF(F19=0, 0, 1-(H19/F19)) | H19: =IF(E19=0, 0, I19/E19) | I19: =SUMIFS('08_Sales_Orders'!$I$3:$I$62,'08_Sales_Orders'!$B$3:$B$62,A19,'08_Sales_Orders'!$D$3:$D$62,D19) | J19: =SUMIFS('08_Sales_Orders'!$J$3:$J$62,'08_Sales_Orders'!$B$3:$B$62,A19,'08_Sales_Orders'!$D$3:$D$62,D19) | K19: =SUMIFS('08_Sales_Orders'!$K$3:$K$62,'08_Sales_Orders'!$B$3:$B$62,A19,'08_Sales_Orders'!$D$3:$D$62,D19) | L19: =SUMIFS('08_Sales_Orders'!$L$3:$L$62,'08_Sales_Orders'!$B$3:$B$62,A19,'08_Sales_Orders'!$D$3:$D$62,D19) | M19: =SUMIFS('08_Sales_Orders'!$M$3:$M$62,'08_Sales_Orders'!$B$3:$B$62,A19,'08_Sales_Orders'!$D$3:$D$62,D19) | N19: 6.8 | O19: 2.9 | P19: ='07_Channel_Costs'!B3*H19 | Q19: ='07_Channel_Costs'!C3 | R19: ='07_Channel_Costs'!D3 | S19: ='07_Channel_Costs'!E3*H19 | T19: =J19*H19 | U19: =J19*'07_Channel_Costs'!F3*N19 | V19: =J19*'07_Channel_Costs'!G3 | W19: =IF(K19=0,0,(E19*(N19+O19) + K19*(P19+Q19+R19+S19) + U19 + V19)/K19) | X19: =IF(K19=0,0,(M19-(E19*(N19+O19) + K19*(P19+Q19+R19+S19) + U19 + V19))/K19) | Y19: =IF(M19=0,"",(M19-(E19*(N19+O19) + K19*(P19+Q19+R19+S19) + U19 + V19))/M19) | Z19: =M19-(E19*(N19+O19) + K19*(P19+Q19+R19+S19) + U19 + V19) | AA19: =IF(Y19>=0.4,"🚀 SCALE",IF(Y19>=0.25,"⚙ OPTIMIZE",IF(Y19>=0,"⚠ REVIEW","🔴 KILL")))
A20: SKU-008 | B20: Rose Hip Facial Oil 30ml | C20: Facial Oil | D20: DTC | E20: =SUMIFS('08_Sales_Orders'!$E$3:$E$62,'08_Sales_Orders'!$B$3:$B$62,A20,'08_Sales_Orders'!$D$3:$D$62,D20) | F20: 35.99 | G20: =IF(F20=0, 0, 1-(H20/F20)) | H20: =IF(E20=0, 0, I20/E20) | I20: =SUMIFS('08_Sales_Orders'!$I$3:$I$62,'08_Sales_Orders'!$B$3:$B$62,A20,'08_Sales_Orders'!$D$3:$D$62,D20) | J20: =SUMIFS('08_Sales_Orders'!$J$3:$J$62,'08_Sales_Orders'!$B$3:$B$62,A20,'08_Sales_Orders'!$D$3:$D$62,D20) | K20: =SUMIFS('08_Sales_Orders'!$K$3:$K$62,'08_Sales_Orders'!$B$3:$B$62,A20,'08_Sales_Orders'!$D$3:$D$62,D20) | L20: =SUMIFS('08_Sales_Orders'!$L$3:$L$62,'08_Sales_Orders'!$B$3:$B$62,A20,'08_Sales_Orders'!$D$3:$D$62,D20) | M20: =SUMIFS('08_Sales_Orders'!$M$3:$M$62,'08_Sales_Orders'!$B$3:$B$62,A20,'08_Sales_Orders'!$D$3:$D$62,D20) | N20: 6.8 | O20: 2.9 | P20: ='07_Channel_Costs'!B4*H20 | Q20: ='07_Channel_Costs'!C4 | R20: ='07_Channel_Costs'!D4 | S20: ='07_Channel_Costs'!E4*H20 | T20: =J20*H20 | U20: =J20*'07_Channel_Costs'!F4*N20 | V20: =J20*'07_Channel_Costs'!G4 | W20: =IF(K20=0,0,(E20*(N20+O20) + K20*(P20+Q20+R20+S20) + U20 + V20)/K20) | X20: =IF(K20=0,0,(M20-(E20*(N20+O20) + K20*(P20+Q20+R20+S20) + U20 + V20))/K20) | Y20: =IF(M20=0,"",(M20-(E20*(N20+O20) + K20*(P20+Q20+R20+S20) + U20 + V20))/M20) | Z20: =M20-(E20*(N20+O20) + K20*(P20+Q20+R20+S20) + U20 + V20) | AA20: =IF(Y20>=0.4,"🚀 SCALE",IF(Y20>=0.25,"⚙ OPTIMIZE",IF(Y20>=0,"⚠ REVIEW","🔴 KILL")))
A21: SKU-009 | B21: Ceramide Barrier Repair Cream 50ml | C21: Cream | D21: Amazon | E21: =SUMIFS('08_Sales_Orders'!$E$3:$E$62,'08_Sales_Orders'!$B$3:$B$62,A21,'08_Sales_Orders'!$D$3:$D$62,D21) | F21: 29.99 | G21: =IF(F21=0, 0, 1-(H21/F21)) | H21: =IF(E21=0, 0, I21/E21) | I21: =SUMIFS('08_Sales_Orders'!$I$3:$I$62,'08_Sales_Orders'!$B$3:$B$62,A21,'08_Sales_Orders'!$D$3:$D$62,D21) | J21: =SUMIFS('08_Sales_Orders'!$J$3:$J$62,'08_Sales_Orders'!$B$3:$B$62,A21,'08_Sales_Orders'!$D$3:$D$62,D21) | K21: =SUMIFS('08_Sales_Orders'!$K$3:$K$62,'08_Sales_Orders'!$B$3:$B$62,A21,'08_Sales_Orders'!$D$3:$D$62,D21) | L21: =SUMIFS('08_Sales_Orders'!$L$3:$L$62,'08_Sales_Orders'!$B$3:$B$62,A21,'08_Sales_Orders'!$D$3:$D$62,D21) | M21: =SUMIFS('08_Sales_Orders'!$M$3:$M$62,'08_Sales_Orders'!$B$3:$B$62,A21,'08_Sales_Orders'!$D$3:$D$62,D21) | N21: 5.6 | O21: 2.6 | P21: ='07_Channel_Costs'!B3*H21 | Q21: ='07_Channel_Costs'!C3 | R21: ='07_Channel_Costs'!D3 | S21: ='07_Channel_Costs'!E3*H21 | T21: =J21*H21 | U21: =J21*'07_Channel_Costs'!F3*N21 | V21: =J21*'07_Channel_Costs'!G3 | W21: =IF(K21=0,0,(E21*(N21+O21) + K21*(P21+Q21+R21+S21) + U21 + V21)/K21) | X21: =IF(K21=0,0,(M21-(E21*(N21+O21) + K21*(P21+Q21+R21+S21) + U21 + V21))/K21) | Y21: =IF(M21=0,"",(M21-(E21*(N21+O21) + K21*(P21+Q21+R21+S21) + U21 + V21))/M21) | Z21: =M21-(E21*(N21+O21) + K21*(P21+Q21+R21+S21) + U21 + V21) | AA21: =IF(Y21>=0.4,"🚀 SCALE",IF(Y21>=0.25,"⚙ OPTIMIZE",IF(Y21>=0,"⚠ REVIEW","🔴 KILL")))
A22: SKU-009 | B22: Ceramide Barrier Repair Cream 50ml | C22: Cream | D22: DTC | E22: =SUMIFS('08_Sales_Orders'!$E$3:$E$62,'08_Sales_Orders'!$B$3:$B$62,A22,'08_Sales_Orders'!$D$3:$D$62,D22) | F22: 29.99 | G22: =IF(F22=0, 0, 1-(H22/F22)) | H22: =IF(E22=0, 0, I22/E22) | I22: =SUMIFS('08_Sales_Orders'!$I$3:$I$62,'08_Sales_Orders'!$B$3:$B$62,A22,'08_Sales_Orders'!$D$3:$D$62,D22) | J22: =SUMIFS('08_Sales_Orders'!$J$3:$J$62,'08_Sales_Orders'!$B$3:$B$62,A22,'08_Sales_Orders'!$D$3:$D$62,D22) | K22: =SUMIFS('08_Sales_Orders'!$K$3:$K$62,'08_Sales_Orders'!$B$3:$B$62,A22,'08_Sales_Orders'!$D$3:$D$62,D22) | L22: =SUMIFS('08_Sales_Orders'!$L$3:$L$62,'08_Sales_Orders'!$B$3:$B$62,A22,'08_Sales_Orders'!$D$3:$D$62,D22) | M22: =SUMIFS('08_Sales_Orders'!$M$3:$M$62,'08_Sales_Orders'!$B$3:$B$62,A22,'08_Sales_Orders'!$D$3:$D$62,D22) | N22: 5.6 | O22: 2.6 | P22: ='07_Channel_Costs'!B4*H22 | Q22: ='07_Channel_Costs'!C4 | R22: ='07_Channel_Costs'!D4 | S22: ='07_Channel_Costs'!E4*H22 | T22: =J22*H22 | U22: =J22*'07_Channel_Costs'!F4*N22 | V22: =J22*'07_Channel_Costs'!G4 | W22: =IF(K22=0,0,(E22*(N22+O22) + K22*(P22+Q22+R22+S22) + U22 + V22)/K22) | X22: =IF(K22=0,0,(M22-(E22*(N22+O22) + K22*(P22+Q22+R22+S22) + U22 + V22))/K22) | Y22: =IF(M22=0,"",(M22-(E22*(N22+O22) + K22*(P22+Q22+R22+S22) + U22 + V22))/M22) | Z22: =M22-(E22*(N22+O22) + K22*(P22+Q22+R22+S22) + U22 + V22) | AA22: =IF(Y22>=0.4,"🚀 SCALE",IF(Y22>=0.25,"⚙ OPTIMIZE",IF(Y22>=0,"⚠ REVIEW","🔴 KILL")))
A23: SKU-010 | B23: Micellar Cleansing Water 250ml | C23: Cleanser | D23: Amazon | E23: =SUMIFS('08_Sales_Orders'!$E$3:$E$62,'08_Sales_Orders'!$B$3:$B$62,A23,'08_Sales_Orders'!$D$3:$D$62,D23) | F23: 18.99 | G23: =IF(F23=0, 0, 1-(H23/F23)) | H23: =IF(E23=0, 0, I23/E23) | I23: =SUMIFS('08_Sales_Orders'!$I$3:$I$62,'08_Sales_Orders'!$B$3:$B$62,A23,'08_Sales_Orders'!$D$3:$D$62,D23) | J23: =SUMIFS('08_Sales_Orders'!$J$3:$J$62,'08_Sales_Orders'!$B$3:$B$62,A23,'08_Sales_Orders'!$D$3:$D$62,D23) | K23: =SUMIFS('08_Sales_Orders'!$K$3:$K$62,'08_Sales_Orders'!$B$3:$B$62,A23,'08_Sales_Orders'!$D$3:$D$62,D23) | L23: =SUMIFS('08_Sales_Orders'!$L$3:$L$62,'08_Sales_Orders'!$B$3:$B$62,A23,'08_Sales_Orders'!$D$3:$D$62,D23) | M23: =SUMIFS('08_Sales_Orders'!$M$3:$M$62,'08_Sales_Orders'!$B$3:$B$62,A23,'08_Sales_Orders'!$D$3:$D$62,D23) | N23: 3.2 | O23: 2.05 | P23: ='07_Channel_Costs'!B3*H23 | Q23: ='07_Channel_Costs'!C3 | R23: ='07_Channel_Costs'!D3 | S23: ='07_Channel_Costs'!E3*H23 | T23: =J23*H23 | U23: =J23*'07_Channel_Costs'!F3*N23 | V23: =J23*'07_Channel_Costs'!G3 | W23: =IF(K23=0,0,(E23*(N23+O23) + K23*(P23+Q23+R23+S23) + U23 + V23)/K23) | X23: =IF(K23=0,0,(M23-(E23*(N23+O23) + K23*(P23+Q23+R23+S23) + U23 + V23))/K23) | Y23: =IF(M23=0,"",(M23-(E23*(N23+O23) + K23*(P23+Q23+R23+S23) + U23 + V23))/M23) | Z23: =M23-(E23*(N23+O23) + K23*(P23+Q23+R23+S23) + U23 + V23) | AA23: =IF(Y23>=0.4,"🚀 SCALE",IF(Y23>=0.25,"⚙ OPTIMIZE",IF(Y23>=0,"⚠ REVIEW","🔴 KILL")))
A24: SKU-010 | B24: Micellar Cleansing Water 250ml | C24: Cleanser | D24: DTC | E24: =SUMIFS('08_Sales_Orders'!$E$3:$E$62,'08_Sales_Orders'!$B$3:$B$62,A24,'08_Sales_Orders'!$D$3:$D$62,D24) | F24: 18.99 | G24: =IF(F24=0, 0, 1-(H24/F24)) | H24: =IF(E24=0, 0, I24/E24) | I24: =SUMIFS('08_Sales_Orders'!$I$3:$I$62,'08_Sales_Orders'!$B$3:$B$62,A24,'08_Sales_Orders'!$D$3:$D$62,D24) | J24: =SUMIFS('08_Sales_Orders'!$J$3:$J$62,'08_Sales_Orders'!$B$3:$B$62,A24,'08_Sales_Orders'!$D$3:$D$62,D24) | K24: =SUMIFS('08_Sales_Orders'!$K$3:$K$62,'08_Sales_Orders'!$B$3:$B$62,A24,'08_Sales_Orders'!$D$3:$D$62,D24) | L24: =SUMIFS('08_Sales_Orders'!$L$3:$L$62,'08_Sales_Orders'!$B$3:$B$62,A24,'08_Sales_Orders'!$D$3:$D$62,D24) | M24: =SUMIFS('08_Sales_Orders'!$M$3:$M$62,'08_Sales_Orders'!$B$3:$B$62,A24,'08_Sales_Orders'!$D$3:$D$62,D24) | N24: 3.2 | O24: 2.05 | P24: ='07_Channel_Costs'!B4*H24 | Q24: ='07_Channel_Costs'!C4 | R24: ='07_Channel_Costs'!D4 | S24: ='07_Channel_Costs'!E4*H24 | T24: =J24*H24 | U24: =J24*'07_Channel_Costs'!F4*N24 | V24: =J24*'07_Channel_Costs'!G4 | W24: =IF(K24=0,0,(E24*(N24+O24) + K24*(P24+Q24+R24+S24) + U24 + V24)/K24) | X24: =IF(K24=0,0,(M24-(E24*(N24+O24) + K24*(P24+Q24+R24+S24) + U24 + V24))/K24) | Y24: =IF(M24=0,"",(M24-(E24*(N24+O24) + K24*(P24+Q24+R24+S24) + U24 + V24))/M24) | Z24: =M24-(E24*(N24+O24) + K24*(P24+Q24+R24+S24) + U24 + V24) | AA24: =IF(Y24>=0.4,"🚀 SCALE",IF(Y24>=0.25,"⚙ OPTIMIZE",IF(Y24>=0,"⚠ REVIEW","🔴 KILL")))
A25: SKU-011 | B25: Peptide Firming Serum 30ml | C25: Serum | D25: Amazon | E25: =SUMIFS('08_Sales_Orders'!$E$3:$E$62,'08_Sales_Orders'!$B$3:$B$62,A25,'08_Sales_Orders'!$D$3:$D$62,D25) | F25: 44.99 | G25: =IF(F25=0, 0, 1-(H25/F25)) | H25: =IF(E25=0, 0, I25/E25) | I25: =SUMIFS('08_Sales_Orders'!$I$3:$I$62,'08_Sales_Orders'!$B$3:$B$62,A25,'08_Sales_Orders'!$D$3:$D$62,D25) | J25: =SUMIFS('08_Sales_Orders'!$J$3:$J$62,'08_Sales_Orders'!$B$3:$B$62,A25,'08_Sales_Orders'!$D$3:$D$62,D25) | K25: =SUMIFS('08_Sales_Orders'!$K$3:$K$62,'08_Sales_Orders'!$B$3:$B$62,A25,'08_Sales_Orders'!$D$3:$D$62,D25) | L25: =SUMIFS('08_Sales_Orders'!$L$3:$L$62,'08_Sales_Orders'!$B$3:$B$62,A25,'08_Sales_Orders'!$D$3:$D$62,D25) | M25: =SUMIFS('08_Sales_Orders'!$M$3:$M$62,'08_Sales_Orders'!$B$3:$B$62,A25,'08_Sales_Orders'!$D$3:$D$62,D25) | N25: 9.1 | O25: 3.15 | P25: ='07_Channel_Costs'!B3*H25 | Q25: ='07_Channel_Costs'!C3 | R25: ='07_Channel_Costs'!D3 | S25: ='07_Channel_Costs'!E3*H25 | T25: =J25*H25 | U25: =J25*'07_Channel_Costs'!F3*N25 | V25: =J25*'07_Channel_Costs'!G3 | W25: =IF(K25=0,0,(E25*(N25+O25) + K25*(P25+Q25+R25+S25) + U25 + V25)/K25) | X25: =IF(K25=0,0,(M25-(E25*(N25+O25) + K25*(P25+Q25+R25+S25) + U25 + V25))/K25) | Y25: =IF(M25=0,"",(M25-(E25*(N25+O25) + K25*(P25+Q25+R25+S25) + U25 + V25))/M25) | Z25: =M25-(E25*(N25+O25) + K25*(P25+Q25+R25+S25) + U25 + V25) | AA25: =IF(Y25>=0.4,"🚀 SCALE",IF(Y25>=0.25,"⚙ OPTIMIZE",IF(Y25>=0,"⚠ REVIEW","🔴 KILL")))
A26: SKU-011 | B26: Peptide Firming Serum 30ml | C26: Serum | D26: DTC | E26: =SUMIFS('08_Sales_Orders'!$E$3:$E$62,'08_Sales_Orders'!$B$3:$B$62,A26,'08_Sales_Orders'!$D$3:$D$62,D26) | F26: 44.99 | G26: =IF(F26=0, 0, 1-(H26/F26)) | H26: =IF(E26=0, 0, I26/E26) | I26: =SUMIFS('08_Sales_Orders'!$I$3:$I$62,'08_Sales_Orders'!$B$3:$B$62,A26,'08_Sales_Orders'!$D$3:$D$62,D26) | J26: =SUMIFS('08_Sales_Orders'!$J$3:$J$62,'08_Sales_Orders'!$B$3:$B$62,A26,'08_Sales_Orders'!$D$3:$D$62,D26) | K26: =SUMIFS('08_Sales_Orders'!$K$3:$K$62,'08_Sales_Orders'!$B$3:$B$62,A26,'08_Sales_Orders'!$D$3:$D$62,D26) | L26: =SUMIFS('08_Sales_Orders'!$L$3:$L$62,'08_Sales_Orders'!$B$3:$B$62,A26,'08_Sales_Orders'!$D$3:$D$62,D26) | M26: =SUMIFS('08_Sales_Orders'!$M$3:$M$62,'08_Sales_Orders'!$B$3:$B$62,A26,'08_Sales_Orders'!$D$3:$D$62,D26) | N26: 9.1 | O26: 3.15 | P26: ='07_Channel_Costs'!B4*H26 | Q26: ='07_Channel_Costs'!C4 | R26: ='07_Channel_Costs'!D4 | S26: ='07_Channel_Costs'!E4*H26 | T26: =J26*H26 | U26: =J26*'07_Channel_Costs'!F4*N26 | V26: =J26*'07_Channel_Costs'!G4 | W26: =IF(K26=0,0,(E26*(N26+O26) + K26*(P26+Q26+R26+S26) + U26 + V26)/K26) | X26: =IF(K26=0,0,(M26-(E26*(N26+O26) + K26*(P26+Q26+R26+S26) + U26 + V26))/K26) | Y26: =IF(M26=0,"",(M26-(E26*(N26+O26) + K26*(P26+Q26+R26+S26) + U26 + V26))/M26) | Z26: =M26-(E26*(N26+O26) + K26*(P26+Q26+R26+S26) + U26 + V26) | AA26: =IF(Y26>=0.4,"🚀 SCALE",IF(Y26>=0.25,"⚙ OPTIMIZE",IF(Y26>=0,"⚠ REVIEW","🔴 KILL")))
A27: SKU-012 | B27: Gentle Foaming Cleanser 150ml | C27: Cleanser | D27: Amazon | E27: =SUMIFS('08_Sales_Orders'!$E$3:$E$62,'08_Sales_Orders'!$B$3:$B$62,A27,'08_Sales_Orders'!$D$3:$D$62,D27) | F27: 19.99 | G27: =IF(F27=0, 0, 1-(H27/F27)) | H27: =IF(E27=0, 0, I27/E27) | I27: =SUMIFS('08_Sales_Orders'!$I$3:$I$62,'08_Sales_Orders'!$B$3:$B$62,A27,'08_Sales_Orders'!$D$3:$D$62,D27) | J27: =SUMIFS('08_Sales_Orders'!$J$3:$J$62,'08_Sales_Orders'!$B$3:$B$62,A27,'08_Sales_Orders'!$D$3:$D$62,D27) | K27: =SUMIFS('08_Sales_Orders'!$K$3:$K$62,'08_Sales_Orders'!$B$3:$B$62,A27,'08_Sales_Orders'!$D$3:$D$62,D27) | L27: =SUMIFS('08_Sales_Orders'!$L$3:$L$62,'08_Sales_Orders'!$B$3:$B$62,A27,'08_Sales_Orders'!$D$3:$D$62,D27) | M27: =SUMIFS('08_Sales_Orders'!$M$3:$M$62,'08_Sales_Orders'!$B$3:$B$62,A27,'08_Sales_Orders'!$D$3:$D$62,D27) | N27: 3.5 | O27: 2.15 | P27: ='07_Channel_Costs'!B3*H27 | Q27: ='07_Channel_Costs'!C3 | R27: ='07_Channel_Costs'!D3 | S27: ='07_Channel_Costs'!E3*H27 | T27: =J27*H27 | U27: =J27*'07_Channel_Costs'!F3*N27 | V27: =J27*'07_Channel_Costs'!G3 | W27: =IF(K27=0,0,(E27*(N27+O27) + K27*(P27+Q27+R27+S27) + U27 + V27)/K27) | X27: =IF(K27=0,0,(M27-(E27*(N27+O27) + K27*(P27+Q27+R27+S27) + U27 + V27))/K27) | Y27: =IF(M27=0,"",(M27-(E27*(N27+O27) + K27*(P27+Q27+R27+S27) + U27 + V27))/M27) | Z27: =M27-(E27*(N27+O27) + K27*(P27+Q27+R27+S27) + U27 + V27) | AA27: =IF(Y27>=0.4,"🚀 SCALE",IF(Y27>=0.25,"⚙ OPTIMIZE",IF(Y27>=0,"⚠ REVIEW","🔴 KILL")))
A28: SKU-012 | B28: Gentle Foaming Cleanser 150ml | C28: Cleanser | D28: DTC | E28: =SUMIFS('08_Sales_Orders'!$E$3:$E$62,'08_Sales_Orders'!$B$3:$B$62,A28,'08_Sales_Orders'!$D$3:$D$62,D28) | F28: 19.99 | G28: =IF(F28=0, 0, 1-(H28/F28)) | H28: =IF(E28=0, 0, I28/E28) | I28: =SUMIFS('08_Sales_Orders'!$I$3:$I$62,'08_Sales_Orders'!$B$3:$B$62,A28,'08_Sales_Orders'!$D$3:$D$62,D28) | J28: =SUMIFS('08_Sales_Orders'!$J$3:$J$62,'08_Sales_Orders'!$B$3:$B$62,A28,'08_Sales_Orders'!$D$3:$D$62,D28) | K28: =SUMIFS('08_Sales_Orders'!$K$3:$K$62,'08_Sales_Orders'!$B$3:$B$62,A28,'08_Sales_Orders'!$D$3:$D$62,D28) | L28: =SUMIFS('08_Sales_Orders'!$L$3:$L$62,'08_Sales_Orders'!$B$3:$B$62,A28,'08_Sales_Orders'!$D$3:$D$62,D28) | M28: =SUMIFS('08_Sales_Orders'!$M$3:$M$62,'08_Sales_Orders'!$B$3:$B$62,A28,'08_Sales_Orders'!$D$3:$D$62,D28) | N28: 3.5 | O28: 2.15 | P28: ='07_Channel_Costs'!B4*H28 | Q28: ='07_Channel_Costs'!C4 | R28: ='07_Channel_Costs'!D4 | S28: ='07_Channel_Costs'!E4*H28 | T28: =J28*H28 | U28: =J28*'07_Channel_Costs'!F4*N28 | V28: =J28*'07_Channel_Costs'!G4 | W28: =IF(K28=0,0,(E28*(N28+O28) + K28*(P28+Q28+R28+S28) + U28 + V28)/K28) | X28: =IF(K28=0,0,(M28-(E28*(N28+O28) + K28*(P28+Q28+R28+S28) + U28 + V28))/K28) | Y28: =IF(M28=0,"",(M28-(E28*(N28+O28) + K28*(P28+Q28+R28+S28) + U28 + V28))/M28) | Z28: =M28-(E28*(N28+O28) + K28*(P28+Q28+R28+S28) + U28 + V28) | AA28: =IF(Y28>=0.4,"🚀 SCALE",IF(Y28>=0.25,"⚙ OPTIMIZE",IF(Y28>=0,"⚠ REVIEW","🔴 KILL")))
A29: TOTALS / AVERAGES | E29: =SUM(E5:E28) | I29: =SUM(I5:I28) | J29: =SUM(J5:J28) | K29: =SUM(K5:K28) | L29: =SUM(L5:L28) | M29: =SUM(M5:M28) | W29: =AVERAGE(W5:W28) | X29: =AVERAGE(X5:X28) | Y29: =AVERAGE(Y5:Y28) | Z29: =SUM(Z5:Z28)
A31: All values EX-VAT. DUAL-LENS: Net Units from Sales Orders (econ_units) - always ≥ 0. Net Revenue = Net Units X Net Price + Shipping Income. Total CM = Net Units X CM/unit. Source: sales_orders.csv

Sheet 03_Kill_Optimize_Scale
A1: 03 | KILL / OPTIMIZE / SCALE DECISION MATRIX — SKU X Channel
A2: AMAZON CHANNEL | K2: DTC CHANNEL
A3: SKU ID | B3: SKU Name | C3: Units Sold | D3: Net Price (ex-VAT) | E3: Total VC /unit | F3: CM /unit | G3: CM % | H3: Total CM (€) | I3: Decision | K3: SKU ID | L3: SKU Name | M3: Units Sold | N3: Net Price (ex-VAT) | O3: Total VC /unit | P3: CM /unit | Q3: CM % | R3: Total CM (€) | S3: Decision
A4: ='02_SKU_Channel_PnL'!A5 | B4: ='02_SKU_Channel_PnL'!B5 | C4: ='02_SKU_Channel_PnL'!E5 | D4: ='02_SKU_Channel_PnL'!H5 | E4: ='02_SKU_Channel_PnL'!W5 | F4: ='02_SKU_Channel_PnL'!X5 | G4: ='02_SKU_Channel_PnL'!Y5 | H4: ='02_SKU_Channel_PnL'!Z5 | I4: ='02_SKU_Channel_PnL'!AA5 | K4: ='02_SKU_Channel_PnL'!A6 | L4: ='02_SKU_Channel_PnL'!B6 | M4: ='02_SKU_Channel_PnL'!E6 | N4: ='02_SKU_Channel_PnL'!H6 | O4: ='02_SKU_Channel_PnL'!W6 | P4: ='02_SKU_Channel_PnL'!X6 | Q4: ='02_SKU_Channel_PnL'!Y6 | R4: ='02_SKU_Channel_PnL'!Z6 | S4: ='02_SKU_Channel_PnL'!AA6
A5: ='02_SKU_Channel_PnL'!A7 | B5: ='02_SKU_Channel_PnL'!B7 | C5: ='02_SKU_Channel_PnL'!E7 | D5: ='02_SKU_Channel_PnL'!H7 | E5: ='02_SKU_Channel_PnL'!W7 | F5: ='02_SKU_Channel_PnL'!X7 | G5: ='02_SKU_Channel_PnL'!Y7 | H5: ='02_SKU_Channel_PnL'!Z7 | I5: ='02_SKU_Channel_PnL'!AA7 | K5: ='02_SKU_Channel_PnL'!A8 | L5: ='02_SKU_Channel_PnL'!B8 | M5: ='02_SKU_Channel_PnL'!E8 | N5: ='02_SKU_Channel_PnL'!H8 | O5: ='02_SKU_Channel_PnL'!W8 | P5: ='02_SKU_Channel_PnL'!X8 | Q5: ='02_SKU_Channel_PnL'!Y8 | R5: ='02_SKU_Channel_PnL'!Z8 | S5: ='02_SKU_Channel_PnL'!AA8
A6: ='02_SKU_Channel_PnL'!A9 | B6: ='02_SKU_Channel_PnL'!B9 | C6: ='02_SKU_Channel_PnL'!E9 | D6: ='02_SKU_Channel_PnL'!H9 | E6: ='02_SKU_Channel_PnL'!W9 | F6: ='02_SKU_Channel_PnL'!X9 | G6: ='02_SKU_Channel_PnL'!Y9 | H6: ='02_SKU_Channel_PnL'!Z9 | I6: ='02_SKU_Channel_PnL'!AA9 | K6: ='02_SKU_Channel_PnL'!A10 | L6: ='02_SKU_Channel_PnL'!B10 | M6: ='02_SKU_Channel_PnL'!E10 | N6: ='02_SKU_Channel_PnL'!H10 | O6: ='02_SKU_Channel_PnL'!W10 | P6: ='02_SKU_Channel_PnL'!X10 | Q6: ='02_SKU_Channel_PnL'!Y10 | R6: ='02_SKU_Channel_PnL'!Z10 | S6: ='02_SKU_Channel_PnL'!AA10
A7: ='02_SKU_Channel_PnL'!A11 | B7: ='02_SKU_Channel_PnL'!B11 | C7: ='02_SKU_Channel_PnL'!E11 | D7: ='02_SKU_Channel_PnL'!H11 | E7: ='02_SKU_Channel_PnL'!W11 | F7: ='02_SKU_Channel_PnL'!X11 | G7: ='02_SKU_Channel_PnL'!Y11 | H7: ='02_SKU_Channel_PnL'!Z11 | I7: ='02_SKU_Channel_PnL'!AA11 | K7: ='02_SKU_Channel_PnL'!A12 | L7: ='02_SKU_Channel_PnL'!B12 | M7: ='02_SKU_Channel_PnL'!E12 | N7: ='02_SKU_Channel_PnL'!H12 | O7: ='02_SKU_Channel_PnL'!W12 | P7: ='02_SKU_Channel_PnL'!X12 | Q7: ='02_SKU_Channel_PnL'!Y12 | R7: ='02_SKU_Channel_PnL'!Z12 | S7: ='02_SKU_Channel_PnL'!AA12
A8: ='02_SKU_Channel_PnL'!A13 | B8: ='02_SKU_Channel_PnL'!B13 | C8: ='02_SKU_Channel_PnL'!E13 | D8: ='02_SKU_Channel_PnL'!H13 | E8: ='02_SKU_Channel_PnL'!W13 | F8: ='02_SKU_Channel_PnL'!X13 | G8: ='02_SKU_Channel_PnL'!Y13 | H8: ='02_SKU_Channel_PnL'!Z13 | I8: ='02_SKU_Channel_PnL'!AA13 | K8: ='02_SKU_Channel_PnL'!A14 | L8: ='02_SKU_Channel_PnL'!B14 | M8: ='02_SKU_Channel_PnL'!E14 | N8: ='02_SKU_Channel_PnL'!H14 | O8: ='02_SKU_Channel_PnL'!W14 | P8: ='02_SKU_Channel_PnL'!X14 | Q8: ='02_SKU_Channel_PnL'!Y14 | R8: ='02_SKU_Channel_PnL'!Z14 | S8: ='02_SKU_Channel_PnL'!AA14
A9: ='02_SKU_Channel_PnL'!A15 | B9: ='02_SKU_Channel_PnL'!B15 | C9: ='02_SKU_Channel_PnL'!E15 | D9: ='02_SKU_Channel_PnL'!H15 | E9: ='02_SKU_Channel_PnL'!W15 | F9: ='02_SKU_Channel_PnL'!X15 | G9: ='02_SKU_Channel_PnL'!Y15 | H9: ='02_SKU_Channel_PnL'!Z15 | I9: ='02_SKU_Channel_PnL'!AA15 | K9: ='02_SKU_Channel_PnL'!A16 | L9: ='02_SKU_Channel_PnL'!B16 | M9: ='02_SKU_Channel_PnL'!E16 | N9: ='02_SKU_Channel_PnL'!H16 | O9: ='02_SKU_Channel_PnL'!W16 | P9: ='02_SKU_Channel_PnL'!X16 | Q9: ='02_SKU_Channel_PnL'!Y16 | R9: ='02_SKU_Channel_PnL'!Z16 | S9: ='02_SKU_Channel_PnL'!AA16
A10: ='02_SKU_Channel_PnL'!A17 | B10: ='02_SKU_Channel_PnL'!B17 | C10: ='02_SKU_Channel_PnL'!E17 | D10: ='02_SKU_Channel_PnL'!H17 | E10: ='02_SKU_Channel_PnL'!W17 | F10: ='02_SKU_Channel_PnL'!X17 | G10: ='02_SKU_Channel_PnL'!Y17 | H10: ='02_SKU_Channel_PnL'!Z17 | I10: ='02_SKU_Channel_PnL'!AA17 | K10: ='02_SKU_Channel_PnL'!A18 | L10: ='02_SKU_Channel_PnL'!B18 | M10: ='02_SKU_Channel_PnL'!E18 | N10: ='02_SKU_Channel_PnL'!H18 | O10: ='02_SKU_Channel_PnL'!W18 | P10: ='02_SKU_Channel_PnL'!X18 | Q10: ='02_SKU_Channel_PnL'!Y18 | R10: ='02_SKU_Channel_PnL'!Z18 | S10: ='02_SKU_Channel_PnL'!AA18
A11: ='02_SKU_Channel_PnL'!A19 | B11: ='02_SKU_Channel_PnL'!B19 | C11: ='02_SKU_Channel_PnL'!E19 | D11: ='02_SKU_Channel_PnL'!H19 | E11: ='02_SKU_Channel_PnL'!W19 | F11: ='02_SKU_Channel_PnL'!X19 | G11: ='02_SKU_Channel_PnL'!Y19 | H11: ='02_SKU_Channel_PnL'!Z19 | I11: ='02_SKU_Channel_PnL'!AA19 | K11: ='02_SKU_Channel_PnL'!A20 | L11: ='02_SKU_Channel_PnL'!B20 | M11: ='02_SKU_Channel_PnL'!E20 | N11: ='02_SKU_Channel_PnL'!H20 | O11: ='02_SKU_Channel_PnL'!W20 | P11: ='02_SKU_Channel_PnL'!X20 | Q11: ='02_SKU_Channel_PnL'!Y20 | R11: ='02_SKU_Channel_PnL'!Z20 | S11: ='02_SKU_Channel_PnL'!AA20
A12: ='02_SKU_Channel_PnL'!A21 | B12: ='02_SKU_Channel_PnL'!B21 | C12: ='02_SKU_Channel_PnL'!E21 | D12: ='02_SKU_Channel_PnL'!H21 | E12: ='02_SKU_Channel_PnL'!W21 | F12: ='02_SKU_Channel_PnL'!X21 | G12: ='02_SKU_Channel_PnL'!Y21 | H12: ='02_SKU_Channel_PnL'!Z21 | I12: ='02_SKU_Channel_PnL'!AA21 | K12: ='02_SKU_Channel_PnL'!A22 | L12: ='02_SKU_Channel_PnL'!B22 | M12: ='02_SKU_Channel_PnL'!E22 | N12: ='02_SKU_Channel_PnL'!H22 | O12: ='02_SKU_Channel_PnL'!W22 | P12: ='02_SKU_Channel_PnL'!X22 | Q12: ='02_SKU_Channel_PnL'!Y22 | R12: ='02_SKU_Channel_PnL'!Z22 | S12: ='02_SKU_Channel_PnL'!AA22
A13: ='02_SKU_Channel_PnL'!A23 | B13: ='02_SKU_Channel_PnL'!B23 | C13: ='02_SKU_Channel_PnL'!E23 | D13: ='02_SKU_Channel_PnL'!H23 | E13: ='02_SKU_Channel_PnL'!W23 | F13: ='02_SKU_Channel_PnL'!X23 | G13: ='02_SKU_Channel_PnL'!Y23 | H13: ='02_SKU_Channel_PnL'!Z23 | I13: ='02_SKU_Channel_PnL'!AA23 | K13: ='02_SKU_Channel_PnL'!A24 | L13: ='02_SKU_Channel_PnL'!B24 | M13: ='02_SKU_Channel_PnL'!E24 | N13: ='02_SKU_Channel_PnL'!H24 | O13: ='02_SKU_Channel_PnL'!W24 | P13: ='02_SKU_Channel_PnL'!X24 | Q13: ='02_SKU_Channel_PnL'!Y24 | R13: ='02_SKU_Channel_PnL'!Z24 | S13: ='02_SKU_Channel_PnL'!AA24
A14: ='02_SKU_Channel_PnL'!A25 | B14: ='02_SKU_Channel_PnL'!B25 | C14: ='02_SKU_Channel_PnL'!E25 | D14: ='02_SKU_Channel_PnL'!H25 | E14: ='02_SKU_Channel_PnL'!W25 | F14: ='02_SKU_Channel_PnL'!X25 | G14: ='02_SKU_Channel_PnL'!Y25 | H14: ='02_SKU_Channel_PnL'!Z25 | I14: ='02_SKU_Channel_PnL'!AA25 | K14: ='02_SKU_Channel_PnL'!A26 | L14: ='02_SKU_Channel_PnL'!B26 | M14: ='02_SKU_Channel_PnL'!E26 | N14: ='02_SKU_Channel_PnL'!H26 | O14: ='02_SKU_Channel_PnL'!W26 | P14: ='02_SKU_Channel_PnL'!X26 | Q14: ='02_SKU_Channel_PnL'!Y26 | R14: ='02_SKU_Channel_PnL'!Z26 | S14: ='02_SKU_Channel_PnL'!AA26
A15: ='02_SKU_Channel_PnL'!A27 | B15: ='02_SKU_Channel_PnL'!B27 | C15: ='02_SKU_Channel_PnL'!E27 | D15: ='02_SKU_Channel_PnL'!H27 | E15: ='02_SKU_Channel_PnL'!W27 | F15: ='02_SKU_Channel_PnL'!X27 | G15: ='02_SKU_Channel_PnL'!Y27 | H15: ='02_SKU_Channel_PnL'!Z27 | I15: ='02_SKU_Channel_PnL'!AA27 | K15: ='02_SKU_Channel_PnL'!A28 | L15: ='02_SKU_Channel_PnL'!B28 | M15: ='02_SKU_Channel_PnL'!E28 | N15: ='02_SKU_Channel_PnL'!H28 | O15: ='02_SKU_Channel_PnL'!W28 | P15: ='02_SKU_Channel_PnL'!X28 | Q15: ='02_SKU_Channel_PnL'!Y28 | R15: ='02_SKU_Channel_PnL'!Z28 | S15: ='02_SKU_Channel_PnL'!AA28
A16: TOTAL / AVG | C16: =SUM(C4:C15) | D16: =AVERAGE(D4:D15) | E16: =AVERAGE(E4:E15) | F16: =AVERAGE(F4:F15) | G16: =AVERAGE(G4:G15) | H16: =SUM(H4:H15) | K16: TOTAL / AVG | M16: =SUM(M4:M15) | N16: =AVERAGE(N4:N15) | O16: =AVERAGE(O4:O15) | P16: =AVERAGE(P4:P15) | Q16: =AVERAGE(Q4:Q15) | R16: =SUM(R4:R15)
A19: 💡 Dual-Lens: Net Units (econ_units) always ≥ 0. Thresholds: 🚀 SCALE ≥ 40% | ⚙ OPTIMIZE 25–39% | 🔴 KILL < 25%

Sheet 04_Scenarios
A1: 04 | SCENARIO ANALYSIS — Sensitivity Matrix (9 Scenarios × SKU × Channel)
A2: SCENARIO ASSUMPTIONS (edit deltas in config.json → scenarios)
A3: Price sensitivity | B3: 0.1 | C3: -0.1 | D3: ±% on Base Price
A4: Discount sensitivity | B4: 0.05 | C4: -0.05 | D4: ±pp on channel discount
A5: Ads sensitivity | B5: 0.05 | C5: -0.05 | D5: ±pp on channel ads %
A6: Returns sensitivity | B6: 0.03 | C6: -0.03 | D6: ±pp on channel returns % (expected-value)
A7: SKU INFO | E7: Base Case | G7: Price +10% | I7: Price -10% | K7: Discount +5pp | M7: Discount -5pp | O7: Ads +5pp | Q7: Ads -5pp | S7: Returns +3pp | U7: Returns -3pp
A8: SKU ID | B8: SKU Name | C8: Subcategory | D8: Channel | E8: CM/unit | F8: CM % | G8: CM/unit | H8: CM % | I8: CM/unit | J8: CM % | K8: CM/unit | L8: CM % | M8: CM/unit | N8: CM % | O8: CM/unit | P8: CM % | Q8: CM/unit | R8: CM % | S8: CM/unit | T8: CM % | U8: CM/unit | V8: CM % | W8: Worst Case
A9: SKU-001 | B9: Vitamin C Brightening Serum 30ml | C9: Serum | D9: Amazon | E9: 9.2391 | F9: 0.277948 | G9: 11.4662 | H9: 0.313589 | I9: 7.012 | J9: 0.234387 | K9: 8.067 | L9: 0.256167 | M9: 10.4113 | N9: 0.297551 | O9: 7.5771 | P9: 0.227948 | Q9: 10.9012 | R9: 0.327948 | S9: 8.0259 | T9: 0.24145 | U9: 10.4523 | V9: 0.314446 | W9: 🔴 22.8%
A10: SKU-001 | B10: Vitamin C Brightening Serum 30ml | C10: Serum | D10: DTC | E10: 13.0038 | F10: 0.412935 | G10: 15.7151 | H10: 0.453669 | I10: 10.2924 | J10: 0.363151 | K10: 11.4974 | L10: 0.386579 | M10: 14.5101 | N10: 0.436518 | O10: 11.4292 | P10: 0.362935 | Q10: 14.5783 | R10: 0.462935 | S10: 11.849 | T10: 0.376267 | U10: 14.1585 | V10: 0.449604 | W10: ⚙ 36.3%
A11: SKU-002 | B11: Hyaluronic Acid Moisturiser 50ml | C11: Moisturiser | D11: Amazon | E11: 6.6181 | F11: 0.240306 | G11: 8.4633 | H11: 0.279369 | I11: 4.7729 | J11: 0.192562 | K11: 5.647 | L11: 0.216434 | M11: 7.5893 | N11: 0.26179 | O11: 5.2411 | P11: 0.190306 | Q11: 7.9952 | R11: 0.290306 | S11: 5.5999 | T11: 0.203334 | U11: 7.6364 | V11: 0.277277 | W11: 🔴 19.0%
A12: SKU-002 | B12: Hyaluronic Acid Moisturiser 50ml | C12: Moisturiser | D12: DTC | E12: 9.5284 | F12: 0.365197 | G12: 11.7748 | H12: 0.41027 | I12: 7.2819 | J12: 0.310108 | K12: 8.2803 | L12: 0.336032 | M12: 10.7764 | N12: 0.391292 | O12: 8.2238 | P12: 0.315197 | Q12: 10.8329 | R12: 0.415197 | S12: 8.5596 | T12: 0.328068 | U12: 10.4971 | V12: 0.402326 | W12: ⚙ 31.0%
A13: SKU-003 | B13: Retinol Night Cream 30ml | C13: Cream | D13: Amazon | E13: 11.6931 | F13: 0.286312 | G13: 14.4294 | H13: 0.321193 | I13: 8.9568 | J13: 0.24368 | K13: 10.253 | L13: 0.264996 | M13: 13.1333 | N13: 0.305497 | O13: 9.6511 | P13: 0.236312 | Q13: 13.7352 | R13: 0.336312 | S13: 10.1829 | T13: 0.249334 | U13: 13.2034 | V13: 0.323291 | W13: 🔴 23.6%
A14: SKU-003 | B14: Retinol Night Cream 30ml | C14: Cream | D14: DTC | E14: 16.634 | F14: 0.429918 | G14: 19.9652 | H14: 0.469107 | I14: 13.3027 | J14: 0.38202 | K14: 14.7832 | L14: 0.40456 | M14: 18.4847 | N14: 0.452606 | O14: 14.6994 | P14: 0.379918 | Q14: 18.5685 | R14: 0.479918 | S14: 15.1942 | T14: 0.392707 | U14: 18.0737 | V14: 0.467129 | W14: ⚙ 38.0%
A15: SKU-004 | B15: SPF 50+ Daily Sunscreen 75ml | C15: Sunscreen | D15: Amazon | E15: 4.4771 | F15: 0.204992 | G15: 5.9404 | H15: 0.247266 | I15: 3.0138 | J15: 0.153325 | K15: 3.707 | L15: 0.179159 | M15: 5.2473 | N15: 0.228243 | O15: 3.3851 | P15: 0.154992 | Q15: 5.5692 | R15: 0.254992 | S15: 3.6689 | T15: 0.167987 | U15: 5.2853 | V15: 0.241998 | W15: 🔴 15.3%
A16: SKU-004 | B16: SPF 50+ Daily Sunscreen 75ml | C16: Sunscreen | D16: DTC | E16: 6.518 | F16: 0.315014 | G16: 8.2994 | H16: 0.364649 | I16: 4.7365 | J16: 0.254349 | K16: 5.5282 | L16: 0.282897 | M16: 7.5077 | N16: 0.34375 | O16: 5.4834 | P16: 0.265014 | Q16: 7.5525 | R16: 0.365014 | S16: 5.7502 | T16: 0.277909 | U16: 7.2857 | V16: 0.352118 | W16: ⚙ 25.4%
A17: SKU-005 | B17: AHA/BHA Exfoliating Toner 200ml | C17: Toner | D17: Amazon | E17: 6.0811 | F17: 0.237169 | G17: 7.799 | H17: 0.276517 | I17: 4.3632 | J17: 0.189077 | K17: 5.177 | L17: 0.213123 | M17: 6.9853 | N17: 0.258811 | O17: 4.7991 | P17: 0.187169 | Q17: 7.3632 | R17: 0.287169 | S17: 5.1379 | T17: 0.200383 | U17: 7.0243 | V17: 0.273955 | W17: 🔴 18.7%
A18: SKU-005 | B18: AHA/BHA Exfoliating Toner 200ml | C18: Toner | D18: DTC | E18: 8.6966 | F18: 0.358015 | G18: 10.788 | H18: 0.403741 | I18: 6.6051 | J18: 0.302128 | K18: 7.5346 | L18: 0.328428 | M18: 9.8585 | N18: 0.384488 | O18: 7.482 | P18: 0.308015 | Q18: 9.9111 | R18: 0.408015 | S18: 7.7998 | T18: 0.321099 | U18: 9.5933 | V18: 0.394931 | W18: ⚙ 30.2%
A19: SKU-006 | B19: Niacinamide Pore Minimiser Serum | C19: Serum | D19: Amazon | E19: 7.7476 | F19: 0.254936 | G19: 9.7838 | H19: 0.292669 | I19: 5.7115 | J19: 0.208818 | K19: 6.676 | L19: 0.231877 | M19: 8.8193 | N19: 0.275689 | O19: 6.2281 | P19: 0.204936 | Q19: 9.2672 | R19: 0.304936 | S19: 6.6289 | T19: 0.218125 | U19: 8.8663 | V19: 0.291747 | W19: 🔴 20.5%
A20: SKU-006 | B20: Niacinamide Pore Minimiser Serum | C20: Serum | D20: DTC | E20: 11.0881 | F20: 0.385122 | G20: 13.567 | H20: 0.428384 | I20: 8.6091 | J20: 0.332247 | K20: 9.7109 | L20: 0.357129 | M20: 12.4652 | N20: 0.410168 | O20: 9.6485 | P20: 0.335122 | Q20: 12.5276 | R20: 0.435122 | S20: 10.0233 | T20: 0.348141 | U20: 12.1528 | V20: 0.422103 | W20: ⚙ 33.2%
... A32: SKU-012 | B32: Gentle Foaming Cleanser 150ml | C32: Cleanser | D32: DTC | E32: 4.9113 | F32: 0.272984 | G32: 6.4603 | H32: 0.32644 | I32: 3.3622 | J32: 0.207649 | K32: 4.0507 | L32: 0.238395 | M32: 5.7718 | N32: 0.303932 | O32: 4.0117 | P32: 0.222984 | Q32: 5.8108 | R32: 0.322984 | S32: 4.2425 | T32: 0.235814 | U32: 5.58 | V32: 0.310154 | W32: 🔴 20.8%
A34: Scenarios built dynamically from config.json (9 total). Worst Case = min CM% across all scenarios per SKU × Channel. Returns model: expected-value based (rate × economics) - correct for scenario analysis.

Sheet 05_Working_Capital
A1: 05 | WORKING CAPITAL — Cash Lock Risk Score per SKU × Channel
A2: WORKING CAPITAL ASSUMPTIONS (editable in config.json → working_capital)
A3: Inventory Days (default) | B3: 45 | C3: Days of stock held. Override per SKU in col G.
A4: Sales Period (days) | B4: 90 | C4: Period units_sold was measured over (from sales_orders.csv).
A5: High Risk Threshold | B5: 500 | C5: Cash Lock above this = 🔴 HIGH.
A6: Medium Risk Threshold | B6: 200 | C6: Cash Lock above this = 🟡 MEDIUM.
A7: SKU ID | B7: SKU Name | C7: Channel | D7: Units Sold | E7: COGS /unit | F7: Daily Velocity | G7: Inventory Days | H7: Cash Locked (€) | I7: Payout Days | J7: Float Exposure | K7: Total Exposure | L7: Risk Score
A8: SKU-001 | B8: Vitamin C Brightening Serum 30ml | C8: Amazon | D8: 495 | E8: 6.2 | F8: =D8/$B$4 | G8: 45 | H8: =G8*E8*F8 | I8: 14 | J8: =I8*33.2405*F8 | K8: =H8+J8 | L8: =IF(H8>=$B$5,"🔴 HIGH",IF(H8>=$B$6,"🟡 MEDIUM","🟢 LOW"))
A9: SKU-001 | B9: Vitamin C Brightening Serum 30ml | C9: DTC | D9: 69 | E9: 6.2 | F9: =D9/$B$4 | G9: 45 | H9: =G9*E9*F9 | I9: 3 | J9: =I9*31.491*F9 | K9: =H9+J9 | L9: =IF(H9>=$B$5,"🔴 HIGH",IF(H9>=$B$6,"🟡 MEDIUM","🟢 LOW"))
A10: SKU-002 | B10: Hyaluronic Acid Moisturiser 50ml | C10: Amazon | D10: 366 | E10: 5.4 | F10: =D10/$B$4 | G10: 45 | H10: =G10*E10*F10 | I10: 14 | J10: =I10*27.5405*F10 | K10: =H10+J10 | L10: =IF(H10>=$B$5,"🔴 HIGH",IF(H10>=$B$6,"🟡 MEDIUM","🟢 LOW"))
A11: SKU-002 | B11: Hyaluronic Acid Moisturiser 50ml | C11: DTC | D11: 141 | E11: 5.4 | F11: =D11/$B$4 | G11: 45 | H11: =G11*E11*F11 | I11: 3 | J11: =I11*26.091*F11 | K11: =H11+J11 | L11: =IF(H11>=$B$5,"🔴 HIGH",IF(H11>=$B$6,"🟡 MEDIUM","🟢 LOW"))
A12: SKU-003 | B12: Retinol Night Cream 30ml | C12: Amazon | D12: 0 | E12: 8.5 | F12: =D12/$B$4 | G12: 45 | H12: =G12*E12*F12 | I12: 14 | J12: =I12*40.8405*F12 | K12: =H12+J12 | L12: =IF(H12>=$B$5,"🔴 HIGH",IF(H12>=$B$6,"🟡 MEDIUM","🟢 LOW"))
A13: SKU-003 | B13: Retinol Night Cream 30ml | C13: DTC | D13: 133 | E13: 8.5 | F13: =D13/$B$4 | G13: 45 | H13: =G13*E13*F13 | I13: 3 | J13: =I13*38.691*F13 | K13: =H13+J13 | L13: =IF(H13>=$B$5,"🔴 HIGH",IF(H13>=$B$6,"🟡 MEDIUM","🟢 LOW"))
A14: SKU-004 | B14: SPF 50+ Daily Sunscreen 75ml | C14: Amazon | D14: 165 | E14: 4.1 | F14: =D14/$B$4 | G14: 45 | H14: =G14*E14*F14 | I14: 14 | J14: =I14*21.8405*F14 | K14: =H14+J14 | L14: =IF(H14>=$B$5,"🔴 HIGH",IF(H14>=$B$6,"🟡 MEDIUM","🟢 LOW"))
A15: SKU-004 | B15: SPF 50+ Daily Sunscreen 75ml | C15: DTC | D15: 0 | E15: 4.1 | F15: =D15/$B$4 | G15: 45 | H15: =G15*E15*F15 | I15: 3 | J15: =I15*20.691*F15 | K15: =H15+J15 | L15: =IF(H15>=$B$5,"🔴 HIGH",IF(H15>=$B$6,"🟡 MEDIUM","🟢 LOW"))
A16: SKU-005 | B16: AHA/BHA Exfoliating Toner 200ml | C16: Amazon | D16: 154 | E16: 4.8 | F16: =D16/$B$4 | G16: 45 | H16: =G16*E16*F16 | I16: 14 | J16: =I16*25.6405*F16 | K16: =H16+J16 | L16: =IF(H16>=$B$5,"🔴 HIGH",IF(H16>=$B$6,"🟡 MEDIUM","🟢 LOW"))
A17: SKU-005 | B17: AHA/BHA Exfoliating Toner 200ml | C17: DTC | D17: 119 | E17: 4.8 | F17: =D17/$B$4 | G17: 45 | H17: =G17*E17*F17 | I17: 3 | J17: =I17*24.291*F17 | K17: =H17+J17 | L17: =IF(H17>=$B$5,"🔴 HIGH",IF(H17>=$B$6,"🟡 MEDIUM","🟢 LOW"))
A18: SKU-006 | B18: Niacinamide Pore Minimiser Serum | C18: Amazon | D18: 70 | E18: 5.9 | F18: =D18/$B$4 | G18: 45 | H18: =G18*E18*F18 | I18: 14 | J18: =I18*30.3905*F18 | K18: =H18+J18 | L18: =IF(H18>=$B$5,"🔴 HIGH",IF(H18>=$B$6,"🟡 MEDIUM","🟢 LOW"))
A19: SKU-006 | B19: Niacinamide Pore Minimiser Serum | C19: DTC | D19: 39 | E19: 5.9 | F19: =D19/$B$4 | G19: 45 | H19: =G19*E19*F19 | I19: 3 | J19: =I19*28.791*F19 | K19: =H19+J19 | L19: =IF(H19>=$B$5,"🔴 HIGH",IF(H19>=$B$6,"🟡 MEDIUM","🟢 LOW"))
A20: SKU-007 | B20: Collagen Boosting Eye Cream 15ml | C20: Amazon | D20: 0 | E20: 7.2 | F20: =D20/$B$4 | G20: 45 | H20: =G20*E20*F20 | I20: 14 | J20: =I20*37.0405*F20 | K20: =H20+J20 | L20: =IF(H20>=$B$5,"🔴 HIGH",IF(H20>=$B$6,"🟡 MEDIUM","🟢 LOW"))
A21: SKU-007 | B21: Collagen Boosting Eye Cream 15ml | C21: DTC | D21: 224 | E21: 7.2 | F21: =D21/$B$4 | G21: 45 | H21: =G21*E21*F21 | I21: 3 | J21: =I21*35.091*F21 | K21: =H21+J21 | L21: =IF(H21>=$B$5,"🔴 HIGH",IF(H21>=$B$6,"🟡 MEDIUM","🟢 LOW"))
A22: SKU-008 | B22: Rose Hip Facial Oil 30ml | C22: Amazon | D22: 175 | E22: 6.8 | F22: =D22/$B$4 | G22: 45 | H22: =G22*E22*F22 | I22: 14 | J22: =I22*34.1905*F22 | K22: =H22+J22 | L22: =IF(H22>=$B$5,"🔴 HIGH",IF(H22>=$B$6,"🟡 MEDIUM","🟢 LOW"))
A23: SKU-008 | B23: Rose Hip Facial Oil 30ml | C23: DTC | D23: 75 | E23: 6.8 | F23: =D23/$B$4 | G23: 45 | H23: =G23*E23*F23 | I23: 3 | J23: =I23*32.391*F23 | K23: =H23+J23 | L23: =IF(H23>=$B$5,"🔴 HIGH",IF(H23>=$B$6,"🟡 MEDIUM","🟢 LOW"))
A24: SKU-009 | B24: Ceramide Barrier Repair Cream 50ml | C24: Amazon | D24: 274 | E24: 5.6 | F24: =D24/$B$4 | G24: 45 | H24: =G24*E24*F24 | I24: 14 | J24: =I24*28.4905*F24 | K24: =H24+J24 | L24: =IF(H24>=$B$5,"🔴 HIGH",IF(H24>=$B$6,"🟡 MEDIUM","🟢 LOW"))
A25: SKU-009 | B25: Ceramide Barrier Repair Cream 50ml | C25: DTC | D25: 103 | E25: 5.6 | F25: =D25/$B$4 | G25: 45 | H25: =G25*E25*F25 | I25: 3 | J25: =I25*26.991*F25 | K25: =H25+J25 | L25: =IF(H25>=$B$5,"🔴 HIGH",IF(H25>=$B$6,"🟡 MEDIUM","🟢 LOW"))
A26: SKU-010 | B26: Micellar Cleansing Water 250ml | C26: Amazon | D26: 210 | E26: 3.2 | F26: =D26/$B$4 | G26: 45 | H26: =G26*E26*F26 | I26: 14 | J26: =I26*18.0405*F26 | K26: =H26+J26 | L26: =IF(H26>=$B$5,"🔴 HIGH",IF(H26>=$B$6,"🟡 MEDIUM","🟢 LOW"))
A27: SKU-010 | B27: Micellar Cleansing Water 250ml | C27: DTC | D27: 146 | E27: 3.2 | F27: =D27/$B$4 | G27: 45 | H27: =G27*E27*F27 | I27: 3 | J27: =I27*17.091*F27 | K27: =H27+J27 | L27: =IF(H27>=$B$5,"🔴 HIGH",IF(H27>=$B$6,"🟡 MEDIUM","🟢 LOW"))
A28: SKU-011 | B28: Peptide Firming Serum 30ml | C28: Amazon | D28: 294 | E28: 9.1 | F28: =D28/$B$4 | G28: 45 | H28: =G28*E28*F28 | I28: 14 | J28: =I28*42.7405*F28 | K28: =H28+J28 | L28: =IF(H28>=$B$5,"🔴 HIGH",IF(H28>=$B$6,"🟡 MEDIUM","🟢 LOW"))
A29: SKU-011 | B29: Peptide Firming Serum 30ml | C29: DTC | D29: 286 | E29: 9.1 | F29: =D29/$B$4 | G29: 45 | H29: =G29*E29*F29 | I29: 3 | J29: =I29*40.491*F29 | K29: =H29+J29 | L29: =IF(H29>=$B$5,"🔴 HIGH",IF(H29>=$B$6,"🟡 MEDIUM","🟢 LOW"))
A30: SKU-012 | B30: Gentle Foaming Cleanser 150ml | C30: Amazon | D30: 80 | E30: 3.5 | F30: =D30/$B$4 | G30: 45 | H30: =G30*E30*F30 | I30: 14 | J30: =I30*18.9905*F30 | K30: =H30+J30 | L30: =IF(H30>=$B$5,"🔴 HIGH",IF(H30>=$B$6,"🟡 MEDIUM","🟢 LOW"))
A31: SKU-012 | B31: Gentle Foaming Cleanser 150ml | C31: DTC | D31: 189 | E31: 3.5 | F31: =D31/$B$4 | G31: 45 | H31: =G31*E31*F31 | I31: 3 | J31: =I31*17.991*F31 | K31: =H31+J31 | L31: =IF(H31>=$B$5,"🔴 HIGH",IF(H31>=$B$6,"🟡 MEDIUM","🟢 LOW"))
A32: TOTALS / AVERAGES | D32: =SUM(D8:D31) | F32: =AVERAGE(F8:F31) | H32: =SUM(H8:H31) | J32: =SUM(J8:J31) | K32: =SUM(K8:K31)
A34: 💡 Cash Lock = Inventory Days × COGS/unit × Daily Velocity | Float = Payout Days × Net Price × Daily Velocity | Override col G per SKU.
A35: 📋 Thresholds: 🔴 HIGH > 500 | 🟡 MEDIUM > 200 | 🟢 LOW ≤ 200 — edit in config.json → working_capital.risk_thresholds
A36: Data source: sales_orders.csv (single source of truth). Returns model: expected-value based for scenarios.

Sheet 06_Raw_SKU
A1: 06 | RAW SKU MASTER — Costs & Pricing (All Ex-VAT)
A2: Category: | B2: ='00_Settings'!B6 | D2: Currency (ex-VAT): | E2: ='00_Settings'!B3
A3: SKU ID | B3: SKU Name | C3: Subcategory | D3: Base Price (ex-VAT) | E3: COGS | F3: Packaging | G3: Inbound Freight | H3: Total Var. Cost
A4: SKU-001 | B4: Vitamin C Brightening Serum 30ml | C4: Serum | D4: 34.99 | E4: 6.2 | F4: 1.8 | G4: 1.1 | H4: =E4+F4+G4
A5: SKU-002 | B5: Hyaluronic Acid Moisturiser 50ml | C5: Moisturiser | D5: 28.99 | E5: 5.4 | F5: 1.6 | G5: 0.95 | H5: =E5+F5+G5
A6: SKU-003 | B6: Retinol Night Cream 30ml | C6: Cream | D6: 42.99 | E6: 8.5 | F6: 1.9 | G6: 1.2 | H6: =E6+F6+G6
A7: SKU-004 | B7: SPF 50+ Daily Sunscreen 75ml | C7: Sunscreen | D7: 22.99 | E7: 4.1 | F7: 1.4 | G7: 0.85 | H7: =E7+F7+G7
